Workbook

Sheet README
A1: SOH（在庫管理）シート 使い方
A2: 【ジャンプ】クリックで各シートへ移動
A3: ▶ 操作パネル - 月次の運用手順順に並んだマクロボタンの設置場所
A4: ▶ Dashboard - 原材料×週の在庫（2年分・横軸で見渡せるメイン画面。まずここ）
A5: ▶ Material_Detail - 材料ごとの使用状況（どの材料が何に使われているか）
A6: ▶ PO_Draft_Chemical - 発注書ドラフト（Chemical）
A7: ▶ PO_Draft_Hazardous - 発注書ドラフト（Hazardous Chemical）
A8: ▶ PO_Draft_Substrate - 発注書ドラフト（Substrate）
A9: ▶ PO_Draft_Substrate_Poland - 発注書ドラフト（Substrate・Poland）
A10: ▶ T_Shipments - 発注・着荷の入力（TTAF供給材料はTTAF倉庫への到着実績を表す）
A11: ▶ T_OpeningStock - 期首在庫の入力
A12: ▶ T_StockCount - 棚卸実績の入力
... A78: - 週次バッチ数はPowder & Slurry & Pgm Planの実データ（約36材料シートから抽出）を使用しています。

Sheet 操作パネル
A1: 操作パネル（ボタンの設置場所）
A2: Alt+F8のマクロ一覧は常にアルファベット順になるため、このシートに月次の運用手順の順でボタンを配置します。ボタンの作成・マクロの割り当ては貴社のExcelで一度だけ手動で行ってください（下記の番号・マクロ名の行に重ねて図形を描き、「マクロの登録」で対応するマクロ名を選ぶだけです）。詳しい手順はdocs/SOH_System_Guide.mdを参照してください。
E3: Solution名リスト（RefreshWeeklyBatchesの行判定に使用）
A4: 【毎月・毎週の定型作業】上から順に実行 | E4: 略称（Pgm Plan表記） | F4: 正式名（システム内部名）
A5: 1 | B5: RefreshWeeklyBatches | C5: 「Powder & Slurry & Pgm Plan」の新しい月版が出たら実行 | E5: 20P | F5: SOL-20P
A6: 2 | B6: RefreshBOM | C6: 「Raw Material - Look Up」が更新されたら実行 | E6: 10H | F6: SOL-10H
A7: 3 | B7: RefreshSelfStock | C7: 自社倉庫の現物確認（daily check）を毎週月曜の朝に実施したら実行 | E7: 10H VW | F7: SOL-10H VW
A8: 4 | B8: RefreshTTAFStock | C8: CSA Reportが毎週月曜に届いたら実行（TTAF在庫） | E8: 250D | F8: SOL-250D
A9: 5 | B9: RefreshShipments | C9: CSA Reportが毎週月曜に届いたら実行（発注・着荷） | E9: 85D | F9: SOL-85D
E10: SCH | F10: SOL-SCH
A11: 【任意】Material_Detailの表示調整 | E11: SH | F11: SOL-SH
A12: 6 | B12: HideInactiveIntermediates | C12: しばらく生産予定の無い中間体の行を折りたたむ
A13: 7 | B13: ShowAllIntermediates | C13: 折りたたんだ行をすべて再表示する
A15: 【まれに使う】材料・中間体の追加/削除（取り消せません。事前にバックアップ推奨）
A16: 8 | B16: AddMaterial | C16: 新しい材料(TTAF供給品)をシステムに追加する
A17: 9 | B17: RemoveMaterial | C17: 使わなくなった材料をシステムから削除する
A18: 10 | B18: RemoveIntermediate | C18: 生産中止になった中間体をシステムから削除する

Sheet Dashboard
A1: 選択週を入力（例: W23。現在年の週Noで検索します） | D1: =IF($C$1="","週Noを入力してください（例: W23）",IF($F$1="","該当週が見つかりません（今年の週Noか確認してください）",INDEX(Cal_Weeks!$E$4:$E$107,$F$1)&" が該当週です（VBA導入時は自動でスクロールします）")) | E1: →WeekIndex | F1: =IFERROR(IF(SUMPRODUCT((Cal_Weeks!$C$4:$C$107=Cal_Weeks!$B$1)*(Cal_Weeks!$D$4:$D$107=VALUE(SUBSTITUTE(UPPER(TRIM($C$1)),"W",""))))=0,"",SUMPRODUCT((Cal_Weeks!$C$4:$C$107=Cal_Weeks!$B$1)*(Cal_Weeks!$D$4:$D$107=VALUE(SUBSTITUTE(UPPER(TRIM($C$1)),"W","")))*(Cal_Weeks!$A$4:$A$107))),"")
K3: ='Cal_Weeks'!G4 | L3: =IF(TEXT('Cal_Weeks'!B5,"mmm-yy")<>TEXT('Cal_Weeks'!B4,"mmm-yy"),'Cal_Weeks'!G5,"") | M3: =IF(TEXT('Cal_Weeks'!B6,"mmm-yy")<>TEXT('Cal_Weeks'!B5,"mmm-yy"),'Cal_Weeks'!G6,"") | N3: =IF(TEXT('Cal_Weeks'!B7,"mmm-yy")<>TEXT('Cal_Weeks'!B6,"mmm-yy"),'Cal_Weeks'!G7,"") | O3: =IF(TEXT('Cal_Weeks'!B8,"mmm-yy")<>TEXT('Cal_Weeks'!B7,"mmm-yy"),'Cal_Weeks'!G8,"") | P3: =IF(TEXT('Cal_Weeks'!B9,"mmm-yy")<>TEXT('Cal_Weeks'!B8,"mmm-yy"),'Cal_Weeks'!G9,"") | Q3: =IF(TEXT('Cal_Weeks'!B10,"mmm-yy")<>TEXT('Cal_Weeks'!B9,"mmm-yy"),'Cal_Weeks'!G10,"") | R3: =IF(TEXT('Cal_Weeks'!B11,"mmm-yy")<>TEXT('Cal_Weeks'!B10,"mmm-yy"),'Cal_Weeks'!G11,"") | S3: =IF(TEXT('Cal_Weeks'!B12,"mmm-yy")<>TEXT('Cal_Weeks'!B11,"mmm-yy"),'Cal_Weeks'!G12,"") | T3: =IF(TEXT('Cal_Weeks'!B13,"mmm-yy")<>TEXT('Cal_Weeks'!B12,"mmm-yy"),'Cal_Weeks'!G13,"") | U3: =IF(TEXT('Cal_Weeks'!B14,"mmm-yy")<>TEXT('Cal_Weeks'!B13,"mmm-yy"),'Cal_Weeks'!G14,"") | V3: =IF(TEXT('Cal_Weeks'!B15,"mmm-yy")<>TEXT('Cal_Weeks'!B14,"mmm-yy"),'Cal_Weeks'!G15,"") | W3: =IF(TEXT('Cal_Weeks'!B16,"mmm-yy")<>TEXT('Cal_Weeks'!B15,"mmm-yy"),'Cal_Weeks'!G16,"") | X3: =IF(TEXT('Cal_Weeks'!B17,"mmm-yy")<>TEXT('Cal_Weeks'!B16,"mmm-yy"),'Cal_Weeks'!G17,"") | Y3: =IF(TEXT('Cal_Weeks'!B18,"mmm-yy")<>TEXT('Cal_Weeks'!B17,"mmm-yy"),'Cal_Weeks'!G18,"") | Z3: =IF(TEXT('Cal_Weeks'!B19,"mmm-yy")<>TEXT('Cal_Weeks'!B18,"mmm-yy"),'Cal_Weeks'!G19,"") | AA3: =IF(TEXT('Cal_Weeks'!B20,"mmm-yy")<>TEXT('Cal_Weeks'!B19,"mmm-yy"),'Cal_Weeks'!G20,"") | AB3: =IF(TEXT('Cal_Weeks'!B21,"mmm-yy")<>TEXT('Cal_Weeks'!B20,"mmm-yy"),'Cal_Weeks'!G21,"") | AC3: =IF(TEXT('Cal_Weeks'!B22,"mmm-yy")<>TEXT('Cal_Weeks'!B21,"mmm-yy"),'Cal_Weeks'!G22,"") | AD3: =IF(TEXT('Cal_Weeks'!B23,"mmm-yy")<>TEXT('Cal_Weeks'!B22,"mmm-yy"),'Cal_Weeks'!G23,"") | AE3: =IF(TEXT('Cal_Weeks'!B24,"mmm-yy")<>TEXT('Cal_Weeks'!B23,"mmm-yy"),'Cal_Weeks'!G24,"") | AF3: =IF(TEXT('Cal_Weeks'!B25,"mmm-yy")<>TEXT('Cal_Weeks'!B24,"mmm-yy"),'Cal_Weeks'!G25,"") | AG3: =IF(TEXT('Cal_Weeks'!B26,"mmm-yy")<>TEXT('Cal_Weeks'!B25,"mmm-yy"),'Cal_Weeks'!G26,"") | AH3: =IF(TEXT('Cal_Weeks'!B27,"mmm-yy")<>TEXT('Cal_Weeks'!B26,"mmm-yy"),'Cal_Weeks'!G27,"") | AI3: =IF(TEXT('Cal_Weeks'!B28,"mmm-yy")<>TEXT('Cal_Weeks'!B27,"mmm-yy"),'Cal_Weeks'!G28,"") | AJ3: =IF(TEXT('Cal_Weeks'!B29,"mmm-yy")<>TEXT('Cal_Weeks'!B28,"mmm-yy"),'Cal_Weeks'!G29,"") | AK3: =IF(TEXT('Cal_Weeks'!B30,"mmm-yy")<>TEXT('Cal_Weeks'!B29,"mmm-yy"),'Cal_Weeks'!G30,"") | AL3: =IF(TEXT('Cal_Weeks'!B31,"mmm-yy")<>TEXT('Cal_Weeks'!B30,"mmm-yy"),'Cal_Weeks'!G31,"") | AM3: =IF(TEXT('Cal_Weeks'!B32,"mmm-yy")<>TEXT('Cal_Weeks'!B31,"mmm-yy"),'Cal_Weeks'!G32,"") | AN3: =IF(TEXT('Cal_Weeks'!B33,"mmm-yy")<>TEXT('Cal_Weeks'!B32,"mmm-yy"),'Cal_Weeks'!G33,"") | AO3: =IF(TEXT('Cal_Weeks'!B34,"mmm-yy")<>TEXT('Cal_Weeks'!B33,"mmm-yy"),'Cal_Weeks'!G34,"") | AP3: =IF(TEXT('Cal_Weeks'!B35,"mmm-yy")<>TEXT('Cal_Weeks'!B34,"mmm-yy"),'Cal_Weeks'!G35,"") | AQ3: =IF(TEXT('Cal_Weeks'!B36,"mmm-yy")<>TEXT('Cal_Weeks'!B35,"mmm-yy"),'Cal_Weeks'!G36,"") | AR3: =IF(TEXT('Cal_Weeks'!B37,"mmm-yy")<>TEXT('Cal_Weeks'!B36,"mmm-yy"),'Cal_Weeks'!G37,"") | AS3: =IF(TEXT('Cal_Weeks'!B38,"mmm-yy")<>TEXT('Cal_Weeks'!B37,"mmm-yy"),'Cal_Weeks'!G38,"") | AT3: =IF(TEXT('Cal_Weeks'!B39,"mmm-yy")<>TEXT('Cal_Weeks'!B38,"mmm-yy"),'Cal_Weeks'!G39,"") | AU3: =IF(TEXT('Cal_Weeks'!B40,"mmm-yy")<>TEXT('Cal_Weeks'!B39,"mmm-yy"),'Cal_Weeks'!G40,"") | AV3: =IF(TEXT('Cal_Weeks'!B41,"mmm-yy")<>TEXT('Cal_Weeks'!B40,"mmm-yy"),'Cal_Weeks'!G41,"") | AW3: =IF(TEXT('Cal_Weeks'!B42,"mmm-yy")<>TEXT('Cal_Weeks'!B41,"mmm-yy"),'Cal_Weeks'!G42,"") | AX3: =IF(TEXT('Cal_Weeks'!B43,"mmm-yy")<>TEXT('Cal_Weeks'!B42,"mmm-yy"),'Cal_Weeks'!G43,"") | AY3: =IF(TEXT('Cal_Weeks'!B44,"mmm-yy")<>TEXT('Cal_Weeks'!B43,"mmm-yy"),'Cal_Weeks'!G44,"") | AZ3: =IF(TEXT('Cal_Weeks'!B45,"mmm-yy")<>TEXT('Cal_Weeks'!B44,"mmm-yy"),'Cal_Weeks'!G45,"") | BA3: =IF(TEXT('Cal_Weeks'!B46,"mmm-yy")<>TEXT('Cal_Weeks'!B45,"mmm-yy"),'Cal_Weeks'!G46,"") | BB3: =IF(TEXT('Cal_Weeks'!B47,"mmm-yy")<>TEXT('Cal_Weeks'!B46,"mmm-yy"),'Cal_Weeks'!G47,"") | BC3: =IF(TEXT('Cal_Weeks'!B48,"mmm-yy")<>TEXT('Cal_Weeks'!B47,"mmm-yy"),'Cal_Weeks'!G48,"") | BD3: =IF(TEXT('Cal_Weeks'!B49,"mmm-yy")<>TEXT('Cal_Weeks'!B48,"mmm-yy"),'Cal_Weeks'!G49,"") | BE3: =IF(TEXT('Cal_Weeks'!B50,"mmm-yy")<>TEXT('Cal_Weeks'!B49,"mmm-yy"),'Cal_Weeks'!G50,"") | BF3: =IF(TEXT('Cal_Weeks'!B51,"mmm-yy")<>TEXT('Cal_Weeks'!B50,"mmm-yy"),'Cal_Weeks'!G51,"") | BG3: =IF(TEXT('Cal_Weeks'!B52,"mmm-yy")<>TEXT('Cal_Weeks'!B51,"mmm-yy"),'Cal_Weeks'!G52,"") | BH3: =IF(TEXT('Cal_Weeks'!B53,"mmm-yy")<>TEXT('Cal_Weeks'!B52,"mmm-yy"),'Cal_Weeks'!G53,"") | BI3: =IF(TEXT('Cal_Weeks'!B54,"mmm-yy")<>TEXT('Cal_Weeks'!B53,"mmm-yy"),'Cal_Weeks'!G54,"") | BJ3: =IF(TEXT('Cal_Weeks'!B55,"mmm-yy")<>TEXT('Cal_Weeks'!B54,"mmm-yy"),'Cal_Weeks'!G55,"") | BK3: =IF(TEXT('Cal_Weeks'!B56,"mmm-yy")<>TEXT('Cal_Weeks'!B55,"mmm-yy"),'Cal_Weeks'!G56,"") | BL3: =IF(TEXT('Cal_Weeks'!B57,"mmm-yy")<>TEXT('Cal_Weeks'!B56,"mmm-yy"),'Cal_Weeks'!G57,"") | BM3: =IF(TEXT('Cal_Weeks'!B58,"mmm-yy")<>TEXT('Cal_Weeks'!B57,"mmm-yy"),'Cal_Weeks'!G58,"") | BN3: =IF(TEXT('Cal_Weeks'!B59,"mmm-yy")<>TEXT('Cal_Weeks'!B58,"mmm-yy"),'Cal_Weeks'!G59,"") | BO3: =IF(TEXT('Cal_Weeks'!B60,"mmm-yy")<>TEXT('Cal_Weeks'!B59,"mmm-yy"),'Cal_Weeks'!G60,"") | BP3: =IF(TEXT('Cal_Weeks'!B61,"mmm-yy")<>TEXT('Cal_Weeks'!B60,"mmm-yy"),'Cal_Weeks'!G61,"") | BQ3: =IF(TEXT('Cal_Weeks'!B62,"mmm-yy")<>TEXT('Cal_Weeks'!B61,"mmm-yy"),'Cal_Weeks'!G62,"") | BR3: =IF(TEXT('Cal_Weeks'!B63,"mmm-yy")<>TEXT('Cal_Weeks'!B62,"mmm-yy"),'Cal_Weeks'!G63,"") | BS3: =IF(TEXT('Cal_Weeks'!B64,"mmm-yy")<>TEXT('Cal_Weeks'!B63,"mmm-yy"),'Cal_Weeks'!G64,"") | BT3: =IF(TEXT('Cal_Weeks'!B65,"mmm-yy")<>TEXT('Cal_Weeks'!B64,"mmm-yy"),'Cal_Weeks'!G65,"") | BU3: =IF(TEXT('Cal_Weeks'!B66,"mmm-yy")<>TEXT('Cal_Weeks'!B65,"mmm-yy"),'Cal_Weeks'!G66,"") | BV3: =IF(TEXT('Cal_Weeks'!B67,"mmm-yy")<>TEXT('Cal_Weeks'!B66,"mmm-yy"),'Cal_Weeks'!G67,"") | BW3: =IF(TEXT('Cal_Weeks'!B68,"mmm-yy")<>TEXT('Cal_Weeks'!B67,"mmm-yy"),'Cal_Weeks'!G68,"") | BX3: =IF(TEXT('Cal_Weeks'!B69,"mmm-yy")<>TEXT('Cal_Weeks'!B68,"mmm-yy"),'Cal_Weeks'!G69,"") | BY3: =IF(TEXT('Cal_Weeks'!B70,"mmm-yy")<>TEXT('Cal_Weeks'!B69,"mmm-yy"),'Cal_Weeks'!G70,"") | BZ3: =IF(TEXT('Cal_Weeks'!B71,"mmm-yy")<>TEXT('Cal_Weeks'!B70,"mmm-yy"),'Cal_Weeks'!G71,"") | CA3: =IF(TEXT('Cal_Weeks'!B72,"mmm-yy")<>TEXT('Cal_Weeks'!B71,"mmm-yy"),'Cal_Weeks'!G72,"") | CB3: =IF(TEXT('Cal_Weeks'!B73,"mmm-yy")<>TEXT('Cal_Weeks'!B72,"mmm-yy"),'Cal_Weeks'!G73,"") | CC3: =IF(TEXT('Cal_Weeks'!B74,"mmm-yy")<>TEXT('Cal_Weeks'!B73,"mmm-yy"),'Cal_Weeks'!G74,"") | CD3: =IF(TEXT('Cal_Weeks'!B75,"mmm-yy")<>TEXT('Cal_Weeks'!B74,"mmm-yy"),'Cal_Weeks'!G75,"") | CE3: =IF(TEXT('Cal_Weeks'!B76,"mmm-yy")<>TEXT('Cal_Weeks'!B75,"mmm-yy"),'Cal_Weeks'!G76,"") | CF3: =IF(TEXT('Cal_Weeks'!B77,"mmm-yy")<>TEXT('Cal_Weeks'!B76,"mmm-yy"),'Cal_Weeks'!G77,"") | CG3: =IF(TEXT('Cal_Weeks'!B78,"mmm-yy")<>TEXT('Cal_Weeks'!B77,"mmm-yy"),'Cal_Weeks'!G78,"") | CH3: =IF(TEXT('Cal_Weeks'!B79,"mmm-yy")<>TEXT('Cal_Weeks'!B78,"mmm-yy"),'Cal_Weeks'!G79,"") | CI3: =IF(TEXT('Cal_Weeks'!B80,"mmm-yy")<>TEXT('Cal_Weeks'!B79,"mmm-yy"),'Cal_Weeks'!G80,"") | CJ3: =IF(TEXT('Cal_Weeks'!B81,"mmm-yy")<>TEXT('Cal_Weeks'!B80,"mmm-yy"),'Cal_Weeks'!G81,"") | CK3: =IF(TEXT('Cal_Weeks'!B82,"mmm-yy")<>TEXT('Cal_Weeks'!B81,"mmm-yy"),'Cal_Weeks'!G82,"") | CL3: =IF(TEXT('Cal_Weeks'!B83,"mmm-yy")<>TEXT('Cal_Weeks'!B82,"mmm-yy"),'Cal_Weeks'!G83,"") | CM3: =IF(TEXT('Cal_Weeks'!B84,"mmm-yy")<>TEXT('Cal_Weeks'!B83,"mmm-yy"),'Cal_Weeks'!G84,"") | CN3: =IF(TEXT('Cal_Weeks'!B85,"mmm-yy")<>TEXT('Cal_Weeks'!B84,"mmm-yy"),'Cal_Weeks'!G85,"") | CO3: =IF(TEXT('Cal_Weeks'!B86,"mmm-yy")<>TEXT('Cal_Weeks'!B85,"mmm-yy"),'Cal_Weeks'!G86,"") | CP3: =IF(TEXT('Cal_Weeks'!B87,"mmm-yy")<>TEXT('Cal_Weeks'!B86,"mmm-yy"),'Cal_Weeks'!G87,"") | CQ3: =IF(TEXT('Cal_Weeks'!B88,"mmm-yy")<>TEXT('Cal_Weeks'!B87,"mmm-yy"),'Cal_Weeks'!G88,"") | CR3: =IF(TEXT('Cal_Weeks'!B89,"mmm-yy")<>TEXT('Cal_Weeks'!B88,"mmm-yy"),'Cal_Weeks'!G89,"") | CS3: =IF(TEXT('Cal_Weeks'!B90,"mmm-yy")<>TEXT('Cal_Weeks'!B89,"mmm-yy"),'Cal_Weeks'!G90,"") | CT3: =IF(TEXT('Cal_Weeks'!B91,"mmm-yy")<>TEXT('Cal_Weeks'!B90,"mmm-yy"),'Cal_Weeks'!G91,"") | CU3: =IF(TEXT('Cal_Weeks'!B92,"mmm-yy")<>TEXT('Cal_Weeks'!B91,"mmm-yy"),'Cal_Weeks'!G92,"") | CV3: =IF(TEXT('Cal_Weeks'!B93,"mmm-yy")<>TEXT('Cal_Weeks'!B92,"mmm-yy"),'Cal_Weeks'!G93,"") | CW3: =IF(TEXT('Cal_Weeks'!B94,"mmm-yy")<>TEXT('Cal_Weeks'!B93,"mmm-yy"),'Cal_Weeks'!G94,"") | CX3: =IF(TEXT('Cal_Weeks'!B95,"mmm-yy")<>TEXT('Cal_Weeks'!B94,"mmm-yy"),'Cal_Weeks'!G95,"") | CY3: =IF(TEXT('Cal_Weeks'!B96,"mmm-yy")<>TEXT('Cal_Weeks'!B95,"mmm-yy"),'Cal_Weeks'!G96,"") | CZ3: =IF(TEXT('Cal_Weeks'!B97,"mmm-yy")<>TEXT('Cal_Weeks'!B96,"mmm-yy"),'Cal_Weeks'!G97,"") | DA3: =IF(TEXT('Cal_Weeks'!B98,"mmm-yy")<>TEXT('Cal_Weeks'!B97,"mmm-yy"),'Cal_Weeks'!G98,"") | DB3: =IF(TEXT('Cal_Weeks'!B99,"mmm-yy")<>TEXT('Cal_Weeks'!B98,"mmm-yy"),'Cal_Weeks'!G99,"") | DC3: =IF(TEXT('Cal_Weeks'!B100,"mmm-yy")<>TEXT('Cal_Weeks'!B99,"mmm-yy"),'Cal_Weeks'!G100,"") | DD3: =IF(TEXT('Cal_Weeks'!B101,"mmm-yy")<>TEXT('Cal_Weeks'!B100,"mmm-yy"),'Cal_Weeks'!G101,"") | DE3: =IF(TEXT('Cal_Weeks'!B102,"mmm-yy")<>TEXT('Cal_Weeks'!B101,"mmm-yy"),'Cal_Weeks'!G102,"") | DF3: =IF(TEXT('Cal_Weeks'!B103,"mmm-yy")<>TEXT('Cal_Weeks'!B102,"mmm-yy"),'Cal_Weeks'!G103,"") | DG3: =IF(TEXT('Cal_Weeks'!B104,"mmm-yy")<>TEXT('Cal_Weeks'!B103,"mmm-yy"),'Cal_Weeks'!G104,"") | DH3: =IF(TEXT('Cal_Weeks'!B105,"mmm-yy")<>TEXT('Cal_Weeks'!B104,"mmm-yy"),'Cal_Weeks'!G105,"") | DI3: =IF(TEXT('Cal_Weeks'!B106,"mmm-yy")<>TEXT('Cal_Weeks'!B105,"mmm-yy"),'Cal_Weeks'!G106,"") | DJ3: =IF(TEXT('Cal_Weeks'!B107,"mmm-yy")<>TEXT('Cal_Weeks'!B106,"mmm-yy"),'Cal_Weeks'!G107,"")
K4: ='Cal_Weeks'!B4 | L4: ='Cal_Weeks'!B5 | M4: ='Cal_Weeks'!B6 | N4: ='Cal_Weeks'!B7 | O4: ='Cal_Weeks'!B8 | P4: ='Cal_Weeks'!B9 | Q4: ='Cal_Weeks'!B10 | R4: ='Cal_Weeks'!B11 | S4: ='Cal_Weeks'!B12 | T4: ='Cal_Weeks'!B13 | U4: ='Cal_Weeks'!B14 | V4: ='Cal_Weeks'!B15 | W4: ='Cal_Weeks'!B16 | X4: ='Cal_Weeks'!B17 | Y4: ='Cal_Weeks'!B18 | Z4: ='Cal_Weeks'!B19 | AA4: ='Cal_Weeks'!B20 | AB4: ='Cal_Weeks'!B21 | AC4: ='Cal_Weeks'!B22 | AD4: ='Cal_Weeks'!B23 | AE4: ='Cal_Weeks'!B24 | AF4: ='Cal_Weeks'!B25 | AG4: ='Cal_Weeks'!B26 | AH4: ='Cal_Weeks'!B27 | AI4: ='Cal_Weeks'!B28 | AJ4: ='Cal_Weeks'!B29 | AK4: ='Cal_Weeks'!B30 | AL4: ='Cal_Weeks'!B31 | AM4: ='Cal_Weeks'!B32 | AN4: ='Cal_Weeks'!B33 | AO4: ='Cal_Weeks'!B34 | AP4: ='Cal_Weeks'!B35 | AQ4: ='Cal_Weeks'!B36 | AR4: ='Cal_Weeks'!B37 | AS4: ='Cal_Weeks'!B38 | AT4: ='Cal_Weeks'!B39 | AU4: ='Cal_Weeks'!B40 | AV4: ='Cal_Weeks'!B41 | AW4: ='Cal_Weeks'!B42 | AX4: ='Cal_Weeks'!B43 | AY4: ='Cal_Weeks'!B44 | AZ4: ='Cal_Weeks'!B45 | BA4: ='Cal_Weeks'!B46 | BB4: ='Cal_Weeks'!B47 | BC4: ='Cal_Weeks'!B48 | BD4: ='Cal_Weeks'!B49 | BE4: ='Cal_Weeks'!B50 | BF4: ='Cal_Weeks'!B51 | BG4: ='Cal_Weeks'!B52 | BH4: ='Cal_Weeks'!B53 | BI4: ='Cal_Weeks'!B54 | BJ4: ='Cal_Weeks'!B55 | BK4: ='Cal_Weeks'!B56 | BL4: ='Cal_Weeks'!B57 | BM4: ='Cal_Weeks'!B58 | BN4: ='Cal_Weeks'!B59 | BO4: ='Cal_Weeks'!B60 | BP4: ='Cal_Weeks'!B61 | BQ4: ='Cal_Weeks'!B62 | BR4: ='Cal_Weeks'!B63 | BS4: ='Cal_Weeks'!B64 | BT4: ='Cal_Weeks'!B65 | BU4: ='Cal_Weeks'!B66 | BV4: ='Cal_Weeks'!B67 | BW4: ='Cal_Weeks'!B68 | BX4: ='Cal_Weeks'!B69 | BY4: ='Cal_Weeks'!B70 | BZ4: ='Cal_Weeks'!B71 | CA4: ='Cal_Weeks'!B72 | CB4: ='Cal_Weeks'!B73 | CC4: ='Cal_Weeks'!B74 | CD4: ='Cal_Weeks'!B75 | CE4: ='Cal_Weeks'!B76 | CF4: ='Cal_Weeks'!B77 | CG4: ='Cal_Weeks'!B78 | CH4: ='Cal_Weeks'!B79 | CI4: ='Cal_Weeks'!B80 | CJ4: ='Cal_Weeks'!B81 | CK4: ='Cal_Weeks'!B82 | CL4: ='Cal_Weeks'!B83 | CM4: ='Cal_Weeks'!B84 | CN4: ='Cal_Weeks'!B85 | CO4: ='Cal_Weeks'!B86 | CP4: ='Cal_Weeks'!B87 | CQ4: ='Cal_Weeks'!B88 | CR4: ='Cal_Weeks'!B89 | CS4: ='Cal_Weeks'!B90 | CT4: ='Cal_Weeks'!B91 | CU4: ='Cal_Weeks'!B92 | CV4: ='Cal_Weeks'!B93 | CW4: ='Cal_Weeks'!B94 | CX4: ='Cal_Weeks'!B95 | CY4: ='Cal_Weeks'!B96 | CZ4: ='Cal_Weeks'!B97 | DA4: ='Cal_Weeks'!B98 | DB4: ='Cal_Weeks'!B99 | DC4: ='Cal_Weeks'!B100 | DD4: ='Cal_Weeks'!B101 | DE4: ='Cal_Weeks'!B102 | DF4: ='Cal_Weeks'!B103 | DG4: ='Cal_Weeks'!B104 | DH4: ='Cal_Weeks'!B105 | DI4: ='Cal_Weeks'!B106 | DJ4: ='Cal_Weeks'!B107
K5: ='Cal_Weeks'!D4 | L5: ='Cal_Weeks'!D5 | M5: ='Cal_Weeks'!D6 | N5: ='Cal_Weeks'!D7 | O5: ='Cal_Weeks'!D8 | P5: ='Cal_Weeks'!D9 | Q5: ='Cal_Weeks'!D10 | R5: ='Cal_Weeks'!D11 | S5: ='Cal_Weeks'!D12 | T5: ='Cal_Weeks'!D13 | U5: ='Cal_Weeks'!D14 | V5: ='Cal_Weeks'!D15 | W5: ='Cal_Weeks'!D16 | X5: ='Cal_Weeks'!D17 | Y5: ='Cal_Weeks'!D18 | Z5: ='Cal_Weeks'!D19 | AA5: ='Cal_Weeks'!D20 | AB5: ='Cal_Weeks'!D21 | AC5: ='Cal_Weeks'!D22 | AD5: ='Cal_Weeks'!D23 | AE5: ='Cal_Weeks'!D24 | AF5: ='Cal_Weeks'!D25 | AG5: ='Cal_Weeks'!D26 | AH5: ='Cal_Weeks'!D27 | AI5: ='Cal_Weeks'!D28 | AJ5: ='Cal_Weeks'!D29 | AK5: ='Cal_Weeks'!D30 | AL5: ='Cal_Weeks'!D31 | AM5: ='Cal_Weeks'!D32 | AN5: ='Cal_Weeks'!D33 | AO5: ='Cal_Weeks'!D34 | AP5: ='Cal_Weeks'!D35 | AQ5: ='Cal_Weeks'!D36 | AR5: ='Cal_Weeks'!D37 | AS5: ='Cal_Weeks'!D38 | AT5: ='Cal_Weeks'!D39 | AU5: ='Cal_Weeks'!D40 | AV5: ='Cal_Weeks'!D41 | AW5: ='Cal_Weeks'!D42 | AX5: ='Cal_Weeks'!D43 | AY5: ='Cal_Weeks'!D44 | AZ5: ='Cal_Weeks'!D45 | BA5: ='Cal_Weeks'!D46 | BB5: ='Cal_Weeks'!D47 | BC5: ='Cal_Weeks'!D48 | BD5: ='Cal_Weeks'!D49 | BE5: ='Cal_Weeks'!D50 | BF5: ='Cal_Weeks'!D51 | BG5: ='Cal_Weeks'!D52 | BH5: ='Cal_Weeks'!D53 | BI5: ='Cal_Weeks'!D54 | BJ5: ='Cal_Weeks'!D55 | BK5: ='Cal_Weeks'!D56 | BL5: ='Cal_Weeks'!D57 | BM5: ='Cal_Weeks'!D58 | BN5: ='Cal_Weeks'!D59 | BO5: ='Cal_Weeks'!D60 | BP5: ='Cal_Weeks'!D61 | BQ5: ='Cal_Weeks'!D62 | BR5: ='Cal_Weeks'!D63 | BS5: ='Cal_Weeks'!D64 | BT5: ='Cal_Weeks'!D65 | BU5: ='Cal_Weeks'!D66 | BV5: ='Cal_Weeks'!D67 | BW5: ='Cal_Weeks'!D68 | BX5: ='Cal_Weeks'!D69 | BY5: ='Cal_Weeks'!D70 | BZ5: ='Cal_Weeks'!D71 | CA5: ='Cal_Weeks'!D72 | CB5: ='Cal_Weeks'!D73 | CC5: ='Cal_Weeks'!D74 | CD5: ='Cal_Weeks'!D75 | CE5: ='Cal_Weeks'!D76 | CF5: ='Cal_Weeks'!D77 | CG5: ='Cal_Weeks'!D78 | CH5: ='Cal_Weeks'!D79 | CI5: ='Cal_Weeks'!D80 | CJ5: ='Cal_Weeks'!D81 | CK5: ='Cal_Weeks'!D82 | CL5: ='Cal_Weeks'!D83 | CM5: ='Cal_Weeks'!D84 | CN5: ='Cal_Weeks'!D85 | CO5: ='Cal_Weeks'!D86 | CP5: ='Cal_Weeks'!D87 | CQ5: ='Cal_Weeks'!D88 | CR5: ='Cal_Weeks'!D89 | CS5: ='Cal_Weeks'!D90 | CT5: ='Cal_Weeks'!D91 | CU5: ='Cal_Weeks'!D92 | CV5: ='Cal_Weeks'!D93 | CW5: ='Cal_Weeks'!D94 | CX5: ='Cal_Weeks'!D95 | CY5: ='Cal_Weeks'!D96 | CZ5: ='Cal_Weeks'!D97 | DA5: ='Cal_Weeks'!D98 | DB5: ='Cal_Weeks'!D99 | DC5: ='Cal_Weeks'!D100 | DD5: ='Cal_Weeks'!D101 | DE5: ='Cal_Weeks'!D102 | DF5: ='Cal_Weeks'!D103 | DG5: ='Cal_Weeks'!D104 | DH5: ='Cal_Weeks'!D105 | DI5: ='Cal_Weeks'!D106 | DJ5: ='Cal_Weeks'!D107
A6: Part Name | B6: Description | C6: Category | D6: 基準在庫_下限 | E6: 基準在庫_上限 | F6: 自社在庫(実績) | G6: TTAF在庫(実績) | H6: 実績週 | I6: 行種別 | J6: 乖離(kg) | K6: ='Cal_Weeks'!E4 | L6: ='Cal_Weeks'!E5 | M6: ='Cal_Weeks'!E6 | N6: ='Cal_Weeks'!E7 | O6: ='Cal_Weeks'!E8 | P6: ='Cal_Weeks'!E9 | Q6: ='Cal_Weeks'!E10 | R6: ='Cal_Weeks'!E11 | S6: ='Cal_Weeks'!E12 | T6: ='Cal_Weeks'!E13 | U6: ='Cal_Weeks'!E14 | V6: ='Cal_Weeks'!E15 | W6: ='Cal_Weeks'!E16 | X6: ='Cal_Weeks'!E17 | Y6: ='Cal_Weeks'!E18 | Z6: ='Cal_Weeks'!E19 | AA6: ='Cal_Weeks'!E20 | AB6: ='Cal_Weeks'!E21 | AC6: ='Cal_Weeks'!E22 | AD6: ='Cal_Weeks'!E23 | AE6: ='Cal_Weeks'!E24 | AF6: ='Cal_Weeks'!E25 | AG6: ='Cal_Weeks'!E26 | AH6: ='Cal_Weeks'!E27 | AI6: ='Cal_Weeks'!E28 | AJ6: ='Cal_Weeks'!E29 | AK6: ='Cal_Weeks'!E30 | AL6: ='Cal_Weeks'!E31 | AM6: ='Cal_Weeks'!E32 | AN6: ='Cal_Weeks'!E33 | AO6: ='Cal_Weeks'!E34 | AP6: ='Cal_Weeks'!E35 | AQ6: ='Cal_Weeks'!E36 | AR6: ='Cal_Weeks'!E37 | AS6: ='Cal_Weeks'!E38 | AT6: ='Cal_Weeks'!E39 | AU6: ='Cal_Weeks'!E40 | AV6: ='Cal_Weeks'!E41 | AW6: ='Cal_Weeks'!E42 | AX6: ='Cal_Weeks'!E43 | AY6: ='Cal_Weeks'!E44 | AZ6: ='Cal_Weeks'!E45 | BA6: ='Cal_Weeks'!E46 | BB6: ='Cal_Weeks'!E47 | BC6: ='Cal_Weeks'!E48 | BD6: ='Cal_Weeks'!E49 | BE6: ='Cal_Weeks'!E50 | BF6: ='Cal_Weeks'!E51 | BG6: ='Cal_Weeks'!E52 | BH6: ='Cal_Weeks'!E53 | BI6: ='Cal_Weeks'!E54 | BJ6: ='Cal_Weeks'!E55 | BK6: ='Cal_Weeks'!E56 | BL6: ='Cal_Weeks'!E57 | BM6: ='Cal_Weeks'!E58 | BN6: ='Cal_Weeks'!E59 | BO6: ='Cal_Weeks'!E60 | BP6: ='Cal_Weeks'!E61 | BQ6: ='Cal_Weeks'!E62 | BR6: ='Cal_Weeks'!E63 | BS6: ='Cal_Weeks'!E64 | BT6: ='Cal_Weeks'!E65 | BU6: ='Cal_Weeks'!E66 | BV6: ='Cal_Weeks'!E67 | BW6: ='Cal_Weeks'!E68 | BX6: ='Cal_Weeks'!E69 | BY6: ='Cal_Weeks'!E70 | BZ6: ='Cal_Weeks'!E71 | CA6: ='Cal_Weeks'!E72 | CB6: ='Cal_Weeks'!E73 | CC6: ='Cal_Weeks'!E74 | CD6: ='Cal_Weeks'!E75 | CE6: ='Cal_Weeks'!E76 | CF6: ='Cal_Weeks'!E77 | CG6: ='Cal_Weeks'!E78 | CH6: ='Cal_Weeks'!E79 | CI6: ='Cal_Weeks'!E80 | CJ6: ='Cal_Weeks'!E81 | CK6: ='Cal_Weeks'!E82 | CL6: ='Cal_Weeks'!E83 | CM6: ='Cal_Weeks'!E84 | CN6: ='Cal_Weeks'!E85 | CO6: ='Cal_Weeks'!E86 | CP6: ='Cal_Weeks'!E87 | CQ6: ='Cal_Weeks'!E88 | CR6: ='Cal_Weeks'!E89 | CS6: ='Cal_Weeks'!E90 | CT6: ='Cal_Weeks'!E91 | CU6: ='Cal_Weeks'!E92 | CV6: ='Cal_Weeks'!E93 | CW6: ='Cal_Weeks'!E94 | CX6: ='Cal_Weeks'!E95 | CY6: ='Cal_Weeks'!E96 | CZ6: ='Cal_Weeks'!E97 | DA6: ='Cal_Weeks'!E98 | DB6: ='Cal_Weeks'!E99 | DC6: ='Cal_Weeks'!E100 | DD6: ='Cal_Weeks'!E101 | DE6: ='Cal_Weeks'!E102 | DF6: ='Cal_Weeks'!E103 | DG6: ='Cal_Weeks'!E104 | DH6: ='Cal_Weeks'!E105 | DI6: ='Cal_Weeks'!E106 | DJ6: ='Cal_Weeks'!E107
A7: 7EP | B7: =IFERROR(INDEX(M_RawMaterials[Description],MATCH($A7,M_RawMaterials[Part Name],0)),"") | C7: =IFERROR(INDEX(M_RawMaterials[Category],MATCH($A7,M_RawMaterials[Part Name],0)),"") | D7: =IFERROR(INDEX(M_RawMaterials[基準在庫下限_要入力],MATCH($A7,M_RawMaterials[Part Name],0)),0) | E7: =IFERROR(INDEX(M_RawMaterials[基準在庫上限_要入力],MATCH($A7,M_RawMaterials[Part Name],0)),0) | F7: =IFERROR(LOOKUP(2,1/('T_SelfStock'!$B$6:$DA$6<>""),'T_SelfStock'!$B$6:$DA$6),"") | G7: =IFERROR(LOOKUP(2,1/('T_TTAFStock'!$B$6:$DA$6<>""),'T_TTAFStock'!$B$6:$DA$6),"") | H7: =IFERROR(LOOKUP(2,1/('T_SelfStock'!$B$6:$DA$6<>""),'T_SelfStock'!$B$5:$DA$5),"") | I7: 理論在庫 | J7: =IFERROR(INDEX('Grid_Stock'!$A2:$DA2,1,LOOKUP(2,1/('T_SelfStock'!$B$6:$DA$6<>""),COLUMN('T_SelfStock'!$B$6:$DA$6)))-INDEX('Grid_TheoreticalStock'!$A2:$DA2,1,LOOKUP(2,1/('T_SelfStock'!$B$6:$DA$6<>""),COLUMN('T_SelfStock'!$B$6:$DA$6))),0) | K7: ='Grid_TheoreticalStock'!B2 | L7: ='Grid_TheoreticalStock'!C2 | M7: ='Grid_TheoreticalStock'!D2 | N7: ='Grid_TheoreticalStock'!E2 | O7: ='Grid_TheoreticalStock'!F2 | P7: ='Grid_TheoreticalStock'!G2 | Q7: ='Grid_TheoreticalStock'!H2 | R7: ='Grid_TheoreticalStock'!I2 | ... DJ7: ='Grid_TheoreticalStock'!DA2
A8: 7EP | B8: =IFERROR(INDEX(M_RawMaterials[Description],MATCH($A8,M_RawMaterials[Part Name],0)),"") | C8: =IFERROR(INDEX(M_RawMaterials[Category],MATCH($A8,M_RawMaterials[Part Name],0)),"") | D8: =IFERROR(INDEX(M_RawMaterials[基準在庫下限_要入力],MATCH($A8,M_RawMaterials[Part Name],0)),0) | E8: =IFERROR(INDEX(M_RawMaterials[基準在庫上限_要入力],MATCH($A8,M_RawMaterials[Part Name],0)),0) | F8: =IFERROR(LOOKUP(2,1/('T_SelfStock'!$B$6:$DA$6<>""),'T_SelfStock'!$B$6:$DA$6),"") | G8: =IFERROR(LOOKUP(2,1/('T_TTAFStock'!$B$6:$DA$6<>""),'T_TTAFStock'!$B$6:$DA$6),"") | H8: =IFERROR(LOOKUP(2,1/('T_SelfStock'!$B$6:$DA$6<>""),'T_SelfStock'!$B$5:$DA$5),"") | I8: 実在庫 | J8: =IFERROR(INDEX('Grid_Stock'!$A2:$DA2,1,LOOKUP(2,1/('T_SelfStock'!$B$6:$DA$6<>""),COLUMN('T_SelfStock'!$B$6:$DA$6)))-INDEX('Grid_TheoreticalStock'!$A2:$DA2,1,LOOKUP(2,1/('T_SelfStock'!$B$6:$DA$6<>""),COLUMN('T_SelfStock'!$B$6:$DA$6))),0) | K8: ='Grid_Stock'!B2 | L8: ='Grid_Stock'!C2 | M8: ='Grid_Stock'!D2 | N8: ='Grid_Stock'!E2 | O8: ='Grid_Stock'!F2 | P8: ='Grid_Stock'!G2 | Q8: ='Grid_Stock'!H2 | R8: ='Grid_Stock'!I2 | ... DJ8: ='Grid_Stock'!DA2
A9: 1EK | B9: =IFERROR(INDEX(M_RawMaterials[Description],MATCH($A9,M_RawMaterials[Part Name],0)),"") | C9: =IFERROR(INDEX(M_RawMaterials[Category],MATCH($A9,M_RawMaterials[Part Name],0)),"") | D9: =IFERROR(INDEX(M_RawMaterials[基準在庫下限_要入力],MATCH($A9,M_RawMaterials[Part Name],0)),0) | E9: =IFERROR(INDEX(M_RawMaterials[基準在庫上限_要入力],MATCH($A9,M_RawMaterials[Part Name],0)),0) | F9: =IFERROR(LOOKUP(2,1/('T_SelfStock'!$B$7:$DA$7<>""),'T_SelfStock'!$B$7:$DA$7),"") | G9: =IFERROR(LOOKUP(2,1/('T_TTAFStock'!$B$7:$DA$7<>""),'T_TTAFStock'!$B$7:$DA$7),"") | H9: =IFERROR(LOOKUP(2,1/('T_SelfStock'!$B$7:$DA$7<>""),'T_SelfStock'!$B$5:$DA$5),"") | I9: 理論在庫 | J9: =IFERROR(INDEX('Grid_Stock'!$A3:$DA3,1,LOOKUP(2,1/('T_SelfStock'!$B$7:$DA$7<>""),COLUMN('T_SelfStock'!$B$7:$DA$7)))-INDEX('Grid_TheoreticalStock'!$A3:$DA3,1,LOOKUP(2,1/('T_SelfStock'!$B$7:$DA$7<>""),COLUMN('T_SelfStock'!$B$7:$DA$7))),0) | K9: ='Grid_TheoreticalStock'!B3 | L9: ='Grid_TheoreticalStock'!C3 | M9: ='Grid_TheoreticalStock'!D3 | N9: ='Grid_TheoreticalStock'!E3 | O9: ='Grid_TheoreticalStock'!F3 | P9: ='Grid_TheoreticalStock'!G3 | Q9: ='Grid_TheoreticalStock'!H3 | R9: ='Grid_TheoreticalStock'!I3 | ... DJ9: ='Grid_TheoreticalStock'!DA3
A10: 1EK | B10: =IFERROR(INDEX(M_RawMaterials[Description],MATCH($A10,M_RawMaterials[Part Name],0)),"") | C10: =IFERROR(INDEX(M_RawMaterials[Category],MATCH($A10,M_RawMaterials[Part Name],0)),"") | D10: =IFERROR(INDEX(M_RawMaterials[基準在庫下限_要入力],MATCH($A10,M_RawMaterials[Part Name],0)),0) | E10: =IFERROR(INDEX(M_RawMaterials[基準在庫上限_要入力],MATCH($A10,M_RawMaterials[Part Name],0)),0) | F10: =IFERROR(LOOKUP(2,1/('T_SelfStock'!$B$7:$DA$7<>""),'T_SelfStock'!$B$7:$DA$7),"") | G10: =IFERROR(LOOKUP(2,1/('T_TTAFStock'!$B$7:$DA$7<>""),'T_TTAFStock'!$B$7:$DA$7),"") | H10: =IFERROR(LOOKUP(2,1/('T_SelfStock'!$B$7:$DA$7<>""),'T_SelfStock'!$B$5:$DA$5),"") | I10: 実在庫 | J10: =IFERROR(INDEX('Grid_Stock'!$A3:$DA3,1,LOOKUP(2,1/('T_SelfStock'!$B$7:$DA$7<>""),COLUMN('T_SelfStock'!$B$7:$DA$7)))-INDEX('Grid_TheoreticalStock'!$A3:$DA3,1,LOOKUP(2,1/('T_SelfStock'!$B$7:$DA$7<>""),COLUMN('T_SelfStock'!$B$7:$DA$7))),0) | K10: ='Grid_Stock'!B3 | L10: ='Grid_Stock'!C3 | M10: ='Grid_Stock'!D3 | N10: ='Grid_Stock'!E3 | O10: ='Grid_Stock'!F3 | P10: ='Grid_Stock'!G3 | Q10: ='Grid_Stock'!H3 | R10: ='Grid_Stock'!I3 | ... DJ10: ='Grid_Stock'!DA3
A11: 4HL | B11: =IFERROR(INDEX(M_RawMaterials[Description],MATCH($A11,M_RawMaterials[Part Name],0)),"") | C11: =IFERROR(INDEX(M_RawMaterials[Category],MATCH($A11,M_RawMaterials[Part Name],0)),"") | D11: =IFERROR(INDEX(M_RawMaterials[基準在庫下限_要入力],MATCH($A11,M_RawMaterials[Part Name],0)),0) | E11: =IFERROR(INDEX(M_RawMaterials[基準在庫上限_要入力],MATCH($A11,M_RawMaterials[Part Name],0)),0) | F11: =IFERROR(LOOKUP(2,1/('T_SelfStock'!$B$8:$DA$8<>""),'T_SelfStock'!$B$8:$DA$8),"") | G11: =IFERROR(LOOKUP(2,1/('T_TTAFStock'!$B$8:$DA$8<>""),'T_TTAFStock'!$B$8:$DA$8),"") | H11: =IFERROR(LOOKUP(2,1/('T_SelfStock'!$B$8:$DA$8<>""),'T_SelfStock'!$B$5:$DA$5),"") | I11: 理論在庫 | J11: =IFERROR(INDEX('Grid_Stock'!$A4:$DA4,1,LOOKUP(2,1/('T_SelfStock'!$B$8:$DA$8<>""),COLUMN('T_SelfStock'!$B$8:$DA$8)))-INDEX('Grid_TheoreticalStock'!$A4:$DA4,1,LOOKUP(2,1/('T_SelfStock'!$B$8:$DA$8<>""),COLUMN('T_SelfStock'!$B$8:$DA$8))),0) | K11: ='Grid_TheoreticalStock'!B4 | L11: ='Grid_TheoreticalStock'!C4 | M11: ='Grid_TheoreticalStock'!D4 | N11: ='Grid_TheoreticalStock'!E4 | O11: ='Grid_TheoreticalStock'!F4 | P11: ='Grid_TheoreticalStock'!G4 | Q11: ='Grid_TheoreticalStock'!H4 | R11: ='Grid_TheoreticalStock'!I4 | ... DJ11: ='Grid_TheoreticalStock'!DA4
A12: 4HL | B12: =IFERROR(INDEX(M_RawMaterials[Description],MATCH($A12,M_RawMaterials[Part Name],0)),"") | C12: =IFERROR(INDEX(M_RawMaterials[Category],MATCH($A12,M_RawMaterials[Part Name],0)),"") | D12: =IFERROR(INDEX(M_RawMaterials[基準在庫下限_要入力],MATCH($A12,M_RawMaterials[Part Name],0)),0) | E12: =IFERROR(INDEX(M_RawMaterials[基準在庫上限_要入力],MATCH($A12,M_RawMaterials[Part Name],0)),0) | F12: =IFERROR(LOOKUP(2,1/('T_SelfStock'!$B$8:$DA$8<>""),'T_SelfStock'!$B$8:$DA$8),"") | G12: =IFERROR(LOOKUP(2,1/('T_TTAFStock'!$B$8:$DA$8<>""),'T_TTAFStock'!$B$8:$DA$8),"") | H12: =IFERROR(LOOKUP(2,1/('T_SelfStock'!$B$8:$DA$8<>""),'T_SelfStock'!$B$5:$DA$5),"") | I12: 実在庫 | J12: =IFERROR(INDEX('Grid_Stock'!$A4:$DA4,1,LOOKUP(2,1/('T_SelfStock'!$B$8:$DA$8<>""),COLUMN('T_SelfStock'!$B$8:$DA$8)))-INDEX('Grid_TheoreticalStock'!$A4:$DA4,1,LOOKUP(2,1/('T_SelfStock'!$B$8:$DA$8<>""),COLUMN('T_SelfStock'!$B$8:$DA$8))),0) | K12: ='Grid_Stock'!B4 | L12: ='Grid_Stock'!C4 | M12: ='Grid_Stock'!D4 | N12: ='Grid_Stock'!E4 | O12: ='Grid_Stock'!F4 | P12: ='Grid_Stock'!G4 | Q12: ='Grid_Stock'!H4 | R12: ='Grid_Stock'!I4 | ... DJ12: ='Grid_Stock'!DA4
A13: 9RN | B13: =IFERROR(INDEX(M_RawMaterials[Description],MATCH($A13,M_RawMaterials[Part Name],0)),"") | C13: =IFERROR(INDEX(M_RawMaterials[Category],MATCH($A13,M_RawMaterials[Part Name],0)),"") | D13: =IFERROR(INDEX(M_RawMaterials[基準在庫下限_要入力],MATCH($A13,M_RawMaterials[Part Name],0)),0) | E13: =IFERROR(INDEX(M_RawMaterials[基準在庫上限_要入力],MATCH($A13,M_RawMaterials[Part Name],0)),0) | F13: =IFERROR(LOOKUP(2,1/('T_SelfStock'!$B$9:$DA$9<>""),'T_SelfStock'!$B$9:$DA$9),"") | G13: =IFERROR(LOOKUP(2,1/('T_TTAFStock'!$B$9:$DA$9<>""),'T_TTAFStock'!$B$9:$DA$9),"") | H13: =IFERROR(LOOKUP(2,1/('T_SelfStock'!$B$9:$DA$9<>""),'T_SelfStock'!$B$5:$DA$5),"") | I13: 理論在庫 | J13: =IFERROR(INDEX('Grid_Stock'!$A5:$DA5,1,LOOKUP(2,1/('T_SelfStock'!$B$9:$DA$9<>""),COLUMN('T_SelfStock'!$B$9:$DA$9)))-INDEX('Grid_TheoreticalStock'!$A5:$DA5,1,LOOKUP(2,1/('T_SelfStock'!$B$9:$DA$9<>""),COLUMN('T_SelfStock'!$B$9:$DA$9))),0) | K13: ='Grid_TheoreticalStock'!B5 | L13: ='Grid_TheoreticalStock'!C5 | M13: ='Grid_TheoreticalStock'!D5 | N13: ='Grid_TheoreticalStock'!E5 | O13: ='Grid_TheoreticalStock'!F5 | P13: ='Grid_TheoreticalStock'!G5 | Q13: ='Grid_TheoreticalStock'!H5 | R13: ='Grid_TheoreticalStock'!I5 | ... DJ13: ='Grid_TheoreticalStock'!DA5
A14: 9RN | B14: =IFERROR(INDEX(M_RawMaterials[Description],MATCH($A14,M_RawMaterials[Part Name],0)),"") | C14: =IFERROR(INDEX(M_RawMaterials[Category],MATCH($A14,M_RawMaterials[Part Name],0)),"") | D14: =IFERROR(INDEX(M_RawMaterials[基準在庫下限_要入力],MATCH($A14,M_RawMaterials[Part Name],0)),0) | E14: =IFERROR(INDEX(M_RawMaterials[基準在庫上限_要入力],MATCH($A14,M_RawMaterials[Part Name],0)),0) | F14: =IFERROR(LOOKUP(2,1/('T_SelfStock'!$B$9:$DA$9<>""),'T_SelfStock'!$B$9:$DA$9),"") | G14: =IFERROR(LOOKUP(2,1/('T_TTAFStock'!$B$9:$DA$9<>""),'T_TTAFStock'!$B$9:$DA$9),"") | H14: =IFERROR(LOOKUP(2,1/('T_SelfStock'!$B$9:$DA$9<>""),'T_SelfStock'!$B$5:$DA$5),"") | I14: 実在庫 | J14: =IFERROR(INDEX('Grid_Stock'!$A5:$DA5,1,LOOKUP(2,1/('T_SelfStock'!$B$9:$DA$9<>""),COLUMN('T_SelfStock'!$B$9:$DA$9)))-INDEX('Grid_TheoreticalStock'!$A5:$DA5,1,LOOKUP(2,1/('T_SelfStock'!$B$9:$DA$9<>""),COLUMN('T_SelfStock'!$B$9:$DA$9))),0) | K14: ='Grid_Stock'!B5 | L14: ='Grid_Stock'!C5 | M14: ='Grid_Stock'!D5 | N14: ='Grid_Stock'!E5 | O14: ='Grid_Stock'!F5 | P14: ='Grid_Stock'!G5 | Q14: ='Grid_Stock'!H5 | R14: ='Grid_Stock'!I5 | ... DJ14: ='Grid_Stock'!DA5
A15: 7CL | B15: =IFERROR(INDEX(M_RawMaterials[Description],MATCH($A15,M_RawMaterials[Part Name],0)),"") | C15: =IFERROR(INDEX(M_RawMaterials[Category],MATCH($A15,M_RawMaterials[Part Name],0)),"") | D15: =IFERROR(INDEX(M_RawMaterials[基準在庫下限_要入力],MATCH($A15,M_RawMaterials[Part Name],0)),0) | E15: =IFERROR(INDEX(M_RawMaterials[基準在庫上限_要入力],MATCH($A15,M_RawMaterials[Part Name],0)),0) | F15: =IFERROR(LOOKUP(2,1/('T_SelfStock'!$B$10:$DA$10<>""),'T_SelfStock'!$B$10:$DA$10),"") | G15: =IFERROR(LOOKUP(2,1/('T_TTAFStock'!$B$10:$DA$10<>""),'T_TTAFStock'!$B$10:$DA$10),"") | H15: =IFERROR(LOOKUP(2,1/('T_SelfStock'!$B$10:$DA$10<>""),'T_SelfStock'!$B$5:$DA$5),"") | I15: 理論在庫 | J15: =IFERROR(INDEX('Grid_Stock'!$A6:$DA6,1,LOOKUP(2,1/('T_SelfStock'!$B$10:$DA$10<>""),COLUMN('T_SelfStock'!$B$10:$DA$10)))-INDEX('Grid_TheoreticalStock'!$A6:$DA6,1,LOOKUP(2,1/('T_SelfStock'!$B$10:$DA$10<>""),COLUMN('T_SelfStock'!$B$10:$DA$10))),0) | K15: ='Grid_TheoreticalStock'!B6 | L15: ='Grid_TheoreticalStock'!C6 | M15: ='Grid_TheoreticalStock'!D6 | N15: ='Grid_TheoreticalStock'!E6 | O15: ='Grid_TheoreticalStock'!F6 | P15: ='Grid_TheoreticalStock'!G6 | Q15: ='Grid_TheoreticalStock'!H6 | R15: ='Grid_TheoreticalStock'!I6 | ... DJ15: ='Grid_TheoreticalStock'!DA6
A16: 7CL | B16: =IFERROR(INDEX(M_RawMaterials[Description],MATCH($A16,M_RawMaterials[Part Name],0)),"") | C16: =IFERROR(INDEX(M_RawMaterials[Category],MATCH($A16,M_RawMaterials[Part Name],0)),"") | D16: =IFERROR(INDEX(M_RawMaterials[基準在庫下限_要入力],MATCH($A16,M_RawMaterials[Part Name],0)),0) | E16: =IFERROR(INDEX(M_RawMaterials[基準在庫上限_要入力],MATCH($A16,M_RawMaterials[Part Name],0)),0) | F16: =IFERROR(LOOKUP(2,1/('T_SelfStock'!$B$10:$DA$10<>""),'T_SelfStock'!$B$10:$DA$10),"") | G16: =IFERROR(LOOKUP(2,1/('T_TTAFStock'!$B$10:$DA$10<>""),'T_TTAFStock'!$B$10:$DA$10),"") | H16: =IFERROR(LOOKUP(2,1/('T_SelfStock'!$B$10:$DA$10<>""),'T_SelfStock'!$B$5:$DA$5),"") | I16: 実在庫 | J16: =IFERROR(INDEX('Grid_Stock'!$A6:$DA6,1,LOOKUP(2,1/('T_SelfStock'!$B$10:$DA$10<>""),COLUMN('T_SelfStock'!$B$10:$DA$10)))-INDEX('Grid_TheoreticalStock'!$A6:$DA6,1,LOOKUP(2,1/('T_SelfStock'!$B$10:$DA$10<>""),COLUMN('T_SelfStock'!$B$10:$DA$10))),0) | K16: ='Grid_Stock'!B6 | L16: ='Grid_Stock'!C6 | M16: ='Grid_Stock'!D6 | N16: ='Grid_Stock'!E6 | O16: ='Grid_Stock'!F6 | P16: ='Grid_Stock'!G6 | Q16: ='Grid_Stock'!H6 | R16: ='Grid_Stock'!I6 | ... DJ16: ='Grid_Stock'!DA6
A17: OJN | B17: =IFERROR(INDEX(M_RawMaterials[Description],MATCH($A17,M_RawMaterials[Part Name],0)),"") | C17: =IFERROR(INDEX(M_RawMaterials[Category],MATCH($A17,M_RawMaterials[Part Name],0)),"") | D17: =IFERROR(INDEX(M_RawMaterials[基準在庫下限_要入力],MATCH($A17,M_RawMaterials[Part Name],0)),0) | E17: =IFERROR(INDEX(M_RawMaterials[基準在庫上限_要入力],MATCH($A17,M_RawMaterials[Part Name],0)),0) | F17: =IFERROR(LOOKUP(2,1/('T_SelfStock'!$B$11:$DA$11<>""),'T_SelfStock'!$B$11:$DA$11),"") | G17: =IFERROR(LOOKUP(2,1/('T_TTAFStock'!$B$11:$DA$11<>""),'T_TTAFStock'!$B$11:$DA$11),"") | H17: =IFERROR(LOOKUP(2,1/('T_SelfStock'!$B$11:$DA$11<>""),'T_SelfStock'!$B$5:$DA$5),"") | I17: 理論在庫 | J17: =IFERROR(INDEX('Grid_Stock'!$A7:$DA7,1,LOOKUP(2,1/('T_SelfStock'!$B$11:$DA$11<>""),COLUMN('T_SelfStock'!$B$11:$DA$11)))-INDEX('Grid_TheoreticalStock'!$A7:$DA7,1,LOOKUP(2,1/('T_SelfStock'!$B$11:$DA$11<>""),COLUMN('T_SelfStock'!$B$11:$DA$11))),0) | K17: ='Grid_TheoreticalStock'!B7 | L17: ='Grid_TheoreticalStock'!C7 | M17: ='Grid_TheoreticalStock'!D7 | N17: ='Grid_TheoreticalStock'!E7 | O17: ='Grid_TheoreticalStock'!F7 | P17: ='Grid_TheoreticalStock'!G7 | Q17: ='Grid_TheoreticalStock'!H7 | R17: ='Grid_TheoreticalStock'!I7 | ... DJ17: ='Grid_TheoreticalStock'!DA7
A18: OJN | B18: =IFERROR(INDEX(M_RawMaterials[Description],MATCH($A18,M_RawMaterials[Part Name],0)),"") | C18: =IFERROR(INDEX(M_RawMaterials[Category],MATCH($A18,M_RawMaterials[Part Name],0)),"") | D18: =IFERROR(INDEX(M_RawMaterials[基準在庫下限_要入力],MATCH($A18,M_RawMaterials[Part Name],0)),0) | E18: =IFERROR(INDEX(M_RawMaterials[基準在庫上限_要入力],MATCH($A18,M_RawMaterials[Part Name],0)),0) | F18: =IFERROR(LOOKUP(2,1/('T_SelfStock'!$B$11:$DA$11<>""),'T_SelfStock'!$B$11:$DA$11),"") | G18: =IFERROR(LOOKUP(2,1/('T_TTAFStock'!$B$11:$DA$11<>""),'T_TTAFStock'!$B$11:$DA$11),"") | H18: =IFERROR(LOOKUP(2,1/('T_SelfStock'!$B$11:$DA$11<>""),'T_SelfStock'!$B$5:$DA$5),"") | I18: 実在庫 | J18: =IFERROR(INDEX('Grid_Stock'!$A7:$DA7,1,LOOKUP(2,1/('T_SelfStock'!$B$11:$DA$11<>""),COLUMN('T_SelfStock'!$B$11:$DA$11)))-INDEX('Grid_TheoreticalStock'!$A7:$DA7,1,LOOKUP(2,1/('T_SelfStock'!$B$11:$DA$11<>""),COLUMN('T_SelfStock'!$B$11:$DA$11))),0) | K18: ='Grid_Stock'!B7 | L18: ='Grid_Stock'!C7 | M18: ='Grid_Stock'!D7 | N18: ='Grid_Stock'!E7 | O18: ='Grid_Stock'!F7 | P18: ='Grid_Stock'!G7 | Q18: ='Grid_Stock'!H7 | R18: ='Grid_Stock'!I7 | ... DJ18: ='Grid_Stock'!DA7
A19: TDJ | B19: =IFERROR(INDEX(M_RawMaterials[Description],MATCH($A19,M_RawMaterials[Part Name],0)),"") | C19: =IFERROR(INDEX(M_RawMaterials[Category],MATCH($A19,M_RawMaterials[Part Name],0)),"") | D19: =IFERROR(INDEX(M_RawMaterials[基準在庫下限_要入力],MATCH($A19,M_RawMaterials[Part Name],0)),0) | E19: =IFERROR(INDEX(M_RawMaterials[基準在庫上限_要入力],MATCH($A19,M_RawMaterials[Part Name],0)),0) | F19: =IFERROR(LOOKUP(2,1/('T_SelfStock'!$B$12:$DA$12<>""),'T_SelfStock'!$B$12:$DA$12),"") | G19: =IFERROR(LOOKUP(2,1/('T_TTAFStock'!$B$12:$DA$12<>""),'T_TTAFStock'!$B$12:$DA$12),"") | H19: =IFERROR(LOOKUP(2,1/('T_SelfStock'!$B$12:$DA$12<>""),'T_SelfStock'!$B$5:$DA$5),"") | I19: 理論在庫 | J19: =IFERROR(INDEX('Grid_Stock'!$A8:$DA8,1,LOOKUP(2,1/('T_SelfStock'!$B$12:$DA$12<>""),COLUMN('T_SelfStock'!$B$12:$DA$12)))-INDEX('Grid_TheoreticalStock'!$A8:$DA8,1,LOOKUP(2,1/('T_SelfStock'!$B$12:$DA$12<>""),COLUMN('T_SelfStock'!$B$12:$DA$12))),0) | K19: ='Grid_TheoreticalStock'!B8 | L19: ='Grid_TheoreticalStock'!C8 | M19: ='Grid_TheoreticalStock'!D8 | N19: ='Grid_TheoreticalStock'!E8 | O19: ='Grid_TheoreticalStock'!F8 | P19: ='Grid_TheoreticalStock'!G8 | Q19: ='Grid_TheoreticalStock'!H8 | R19: ='Grid_TheoreticalStock'!I8 | ... DJ19: ='Grid_TheoreticalStock'!DA8
A20: TDJ | B20: =IFERROR(INDEX(M_RawMaterials[Description],MATCH($A20,M_RawMaterials[Part Name],0)),"") | C20: =IFERROR(INDEX(M_RawMaterials[Category],MATCH($A20,M_RawMaterials[Part Name],0)),"") | D20: =IFERROR(INDEX(M_RawMaterials[基準在庫下限_要入力],MATCH($A20,M_RawMaterials[Part Name],0)),0) | E20: =IFERROR(INDEX(M_RawMaterials[基準在庫上限_要入力],MATCH($A20,M_RawMaterials[Part Name],0)),0) | F20: =IFERROR(LOOKUP(2,1/('T_SelfStock'!$B$12:$DA$12<>""),'T_SelfStock'!$B$12:$DA$12),"") | G20: =IFERROR(LOOKUP(2,1/('T_TTAFStock'!$B$12:$DA$12<>""),'T_TTAFStock'!$B$12:$DA$12),"") | H20: =IFERROR(LOOKUP(2,1/('T_SelfStock'!$B$12:$DA$12<>""),'T_SelfStock'!$B$5:$DA$5),"") | I20: 実在庫 | J20: =IFERROR(INDEX('Grid_Stock'!$A8:$DA8,1,LOOKUP(2,1/('T_SelfStock'!$B$12:$DA$12<>""),COLUMN('T_SelfStock'!$B$12:$DA$12)))-INDEX('Grid_TheoreticalStock'!$A8:$DA8,1,LOOKUP(2,1/('T_SelfStock'!$B$12:$DA$12<>""),COLUMN('T_SelfStock'!$B$12:$DA$12))),0) | K20: ='Grid_Stock'!B8 | L20: ='Grid_Stock'!C8 | M20: ='Grid_Stock'!D8 | N20: ='Grid_Stock'!E8 | O20: ='Grid_Stock'!F8 | P20: ='Grid_Stock'!G8 | Q20: ='Grid_Stock'!H8 | R20: ='Grid_Stock'!I8 | ... DJ20: ='Grid_Stock'!DA8
A21: 3TP | B21: =IFERROR(INDEX(M_RawMaterials[Description],MATCH($A21,M_RawMaterials[Part Name],0)),"") | C21: =IFERROR(INDEX(M_RawMaterials[Category],MATCH($A21,M_RawMaterials[Part Name],0)),"") | D21: =IFERROR(INDEX(M_RawMaterials[基準在庫下限_要入力],MATCH($A21,M_RawMaterials[Part Name],0)),0) | E21: =IFERROR(INDEX(M_RawMaterials[基準在庫上限_要入力],MATCH($A21,M_RawMaterials[Part Name],0)),0) | F21: =IFERROR(LOOKUP(2,1/('T_SelfStock'!$B$13:$DA$13<>""),'T_SelfStock'!$B$13:$DA$13),"") | G21: =IFERROR(LOOKUP(2,1/('T_TTAFStock'!$B$13:$DA$13<>""),'T_TTAFStock'!$B$13:$DA$13),"") | H21: =IFERROR(LOOKUP(2,1/('T_SelfStock'!$B$13:$DA$13<>""),'T_SelfStock'!$B$5:$DA$5),"") | I21: 理論在庫 | J21: =IFERROR(INDEX('Grid_Stock'!$A9:$DA9,1,LOOKUP(2,1/('T_SelfStock'!$B$13:$DA$13<>""),COLUMN('T_SelfStock'!$B$13:$DA$13)))-INDEX('Grid_TheoreticalStock'!$A9:$DA9,1,LOOKUP(2,1/('T_SelfStock'!$B$13:$DA$13<>""),COLUMN('T_SelfStock'!$B$13:$DA$13))),0) | K21: ='Grid_TheoreticalStock'!B9 | L21: ='Grid_TheoreticalStock'!C9 | M21: ='Grid_TheoreticalStock'!D9 | N21: ='Grid_TheoreticalStock'!E9 | O21: ='Grid_TheoreticalStock'!F9 | P21: ='Grid_TheoreticalStock'!G9 | Q21: ='Grid_TheoreticalStock'!H9 | R21: ='Grid_TheoreticalStock'!I9 | ... DJ21: ='Grid_TheoreticalStock'!DA9
A22: 3TP | B22: =IFERROR(INDEX(M_RawMaterials[Description],MATCH($A22,M_RawMaterials[Part Name],0)),"") | C22: =IFERROR(INDEX(M_RawMaterials[Category],MATCH($A22,M_RawMaterials[Part Name],0)),"") | D22: =IFERROR(INDEX(M_RawMaterials[基準在庫下限_要入力],MATCH($A22,M_RawMaterials[Part Name],0)),0) | E22: =IFERROR(INDEX(M_RawMaterials[基準在庫上限_要入力],MATCH($A22,M_RawMaterials[Part Name],0)),0) | F22: =IFERROR(LOOKUP(2,1/('T_SelfStock'!$B$13:$DA$13<>""),'T_SelfStock'!$B$13:$DA$13),"") | G22: =IFERROR(LOOKUP(2,1/('T_TTAFStock'!$B$13:$DA$13<>""),'T_TTAFStock'!$B$13:$DA$13),"") | H22: =IFERROR(LOOKUP(2,1/('T_SelfStock'!$B$13:$DA$13<>""),'T_SelfStock'!$B$5:$DA$5),"") | I22: 実在庫 | J22: =IFERROR(INDEX('Grid_Stock'!$A9:$DA9,1,LOOKUP(2,1/('T_SelfStock'!$B$13:$DA$13<>""),COLUMN('T_SelfStock'!$B$13:$DA$13)))-INDEX('Grid_TheoreticalStock'!$A9:$DA9,1,LOOKUP(2,1/('T_SelfStock'!$B$13:$DA$13<>""),COLUMN('T_SelfStock'!$B$13:$DA$13))),0) | K22: ='Grid_Stock'!B9 | L22: ='Grid_Stock'!C9 | M22: ='Grid_Stock'!D9 | N22: ='Grid_Stock'!E9 | O22: ='Grid_Stock'!F9 | P22: ='Grid_Stock'!G9 | Q22: ='Grid_Stock'!H9 | R22: ='Grid_Stock'!I9 | ... DJ22: ='Grid_Stock'!DA9
A23: KEJ | B23: =IFERROR(INDEX(M_RawMaterials[Description],MATCH($A23,M_RawMaterials[Part Name],0)),"") | C23: =IFERROR(INDEX(M_RawMaterials[Category],MATCH($A23,M_RawMaterials[Part Name],0)),"") | D23: =IFERROR(INDEX(M_RawMaterials[基準在庫下限_要入力],MATCH($A23,M_RawMaterials[Part Name],0)),0) | E23: =IFERROR(INDEX(M_RawMaterials[基準在庫上限_要入力],MATCH($A23,M_RawMaterials[Part Name],0)),0) | F23: =IFERROR(LOOKUP(2,1/('T_SelfStock'!$B$14:$DA$14<>""),'T_SelfStock'!$B$14:$DA$14),"") | G23: =IFERROR(LOOKUP(2,1/('T_TTAFStock'!$B$14:$DA$14<>""),'T_TTAFStock'!$B$14:$DA$14),"") | H23: =IFERROR(LOOKUP(2,1/('T_SelfStock'!$B$14:$DA$14<>""),'T_SelfStock'!$B$5:$DA$5),"") | I23: 理論在庫 | J23: =IFERROR(INDEX('Grid_Stock'!$A10:$DA10,1,LOOKUP(2,1/('T_SelfStock'!$B$14:$DA$14<>""),COLUMN('T_SelfStock'!$B$14:$DA$14)))-INDEX('Grid_TheoreticalStock'!$A10:$DA10,1,LOOKUP(2,1/('T_SelfStock'!$B$14:$DA$14<>""),COLUMN('T_SelfStock'!$B$14:$DA$14))),0) | K23: ='Grid_TheoreticalStock'!B10 | L23: ='Grid_TheoreticalStock'!C10 | M23: ='Grid_TheoreticalStock'!D10 | N23: ='Grid_TheoreticalStock'!E10 | O23: ='Grid_TheoreticalStock'!F10 | P23: ='Grid_TheoreticalStock'!G10 | Q23: ='Grid_TheoreticalStock'!H10 | R23: ='Grid_TheoreticalStock'!I10 | ... DJ23: ='Grid_TheoreticalStock'!DA10
A24: KEJ | B24: =IFERROR(INDEX(M_RawMaterials[Description],MATCH($A24,M_RawMaterials[Part Name],0)),"") | C24: =IFERROR(INDEX(M_RawMaterials[Category],MATCH($A24,M_RawMaterials[Part Name],0)),"") | D24: =IFERROR(INDEX(M_RawMaterials[基準在庫下限_要入力],MATCH($A24,M_RawMaterials[Part Name],0)),0) | E24: =IFERROR(INDEX(M_RawMaterials[基準在庫上限_要入力],MATCH($A24,M_RawMaterials[Part Name],0)),0) | F24: =IFERROR(LOOKUP(2,1/('T_SelfStock'!$B$14:$DA$14<>""),'T_SelfStock'!$B$14:$DA$14),"") | G24: =IFERROR(LOOKUP(2,1/('T_TTAFStock'!$B$14:$DA$14<>""),'T_TTAFStock'!$B$14:$DA$14),"") | H24: =IFERROR(LOOKUP(2,1/('T_SelfStock'!$B$14:$DA$14<>""),'T_SelfStock'!$B$5:$DA$5),"") | I24: 実在庫 | J24: =IFERROR(INDEX('Grid_Stock'!$A10:$DA10,1,LOOKUP(2,1/('T_SelfStock'!$B$14:$DA$14<>""),COLUMN('T_SelfStock'!$B$14:$DA$14)))-INDEX('Grid_TheoreticalStock'!$A10:$DA10,1,LOOKUP(2,1/('T_SelfStock'!$B$14:$DA$14<>""),COLUMN('T_SelfStock'!$B$14:$DA$14))),0) | K24: ='Grid_Stock'!B10 | L24: ='Grid_Stock'!C10 | M24: ='Grid_Stock'!D10 | N24: ='Grid_Stock'!E10 | O24: ='Grid_Stock'!F10 | P24: ='Grid_Stock'!G10 | Q24: ='Grid_Stock'!H10 | R24: ='Grid_Stock'!I10 | ... DJ24: ='Grid_Stock'!DA10
A25: JEJ | B25: =IFERROR(INDEX(M_RawMaterials[Description],MATCH($A25,M_RawMaterials[Part Name],0)),"") | C25: =IFERROR(INDEX(M_RawMaterials[Category],MATCH($A25,M_RawMaterials[Part Name],0)),"") | D25: =IFERROR(INDEX(M_RawMaterials[基準在庫下限_要入力],MATCH($A25,M_RawMaterials[Part Name],0)),0) | E25: =IFERROR(INDEX(M_RawMaterials[基準在庫上限_要入力],MATCH($A25,M_RawMaterials[Part Name],0)),0) | F25: =IFERROR(LOOKUP(2,1/('T_SelfStock'!$B$15:$DA$15<>""),'T_SelfStock'!$B$15:$DA$15),"") | G25: =IFERROR(LOOKUP(2,1/('T_TTAFStock'!$B$15:$DA$15<>""),'T_TTAFStock'!$B$15:$DA$15),"") | H25: =IFERROR(LOOKUP(2,1/('T_SelfStock'!$B$15:$DA$15<>""),'T_SelfStock'!$B$5:$DA$5),"") | I25: 理論在庫 | J25: =IFERROR(INDEX('Grid_Stock'!$A11:$DA11,1,LOOKUP(2,1/('T_SelfStock'!$B$15:$DA$15<>""),COLUMN('T_SelfStock'!$B$15:$DA$15)))-INDEX('Grid_TheoreticalStock'!$A11:$DA11,1,LOOKUP(2,1/('T_SelfStock'!$B$15:$DA$15<>""),COLUMN('T_SelfStock'!$B$15:$DA$15))),0) | K25: ='Grid_TheoreticalStock'!B11 | L25: ='Grid_TheoreticalStock'!C11 | M25: ='Grid_TheoreticalStock'!D11 | N25: ='Grid_TheoreticalStock'!E11 | O25: ='Grid_TheoreticalStock'!F11 | P25: ='Grid_TheoreticalStock'!G11 | Q25: ='Grid_TheoreticalStock'!H11 | R25: ='Grid_TheoreticalStock'!I11 | ... DJ25: ='Grid_TheoreticalStock'!DA11
A26: JEJ | B26: =IFERROR(INDEX(M_RawMaterials[Description],MATCH($A26,M_RawMaterials[Part Name],0)),"") | C26: =IFERROR(INDEX(M_RawMaterials[Category],MATCH($A26,M_RawMaterials[Part Name],0)),"") | D26: =IFERROR(INDEX(M_RawMaterials[基準在庫下限_要入力],MATCH($A26,M_RawMaterials[Part Name],0)),0) | E26: =IFERROR(INDEX(M_RawMaterials[基準在庫上限_要入力],MATCH($A26,M_RawMaterials[Part Name],0)),0) | F26: =IFERROR(LOOKUP(2,1/('T_SelfStock'!$B$15:$DA$15<>""),'T_SelfStock'!$B$15:$DA$15),"") | G26: =IFERROR(LOOKUP(2,1/('T_TTAFStock'!$B$15:$DA$15<>""),'T_TTAFStock'!$B$15:$DA$15),"") | H26: =IFERROR(LOOKUP(2,1/('T_SelfStock'!$B$15:$DA$15<>""),'T_SelfStock'!$B$5:$DA$5),"") | I26: 実在庫 | J26: =IFERROR(INDEX('Grid_Stock'!$A11:$DA11,1,LOOKUP(2,1/('T_SelfStock'!$B$15:$DA$15<>""),COLUMN('T_SelfStock'!$B$15:$DA$15)))-INDEX('Grid_TheoreticalStock'!$A11:$DA11,1,LOOKUP(2,1/('T_SelfStock'!$B$15:$DA$15<>""),COLUMN('T_SelfStock'!$B$15:$DA$15))),0) | K26: ='Grid_Stock'!B11 | L26: ='Grid_Stock'!C11 | M26: ='Grid_Stock'!D11 | N26: ='Grid_Stock'!E11 | O26: ='Grid_Stock'!F11 | P26: ='Grid_Stock'!G11 | Q26: ='Grid_Stock'!H11 | R26: ='Grid_Stock'!I11 | ... DJ26: ='Grid_Stock'!DA11
A27: YAN | B27: =IFERROR(INDEX(M_RawMaterials[Description],MATCH($A27,M_RawMaterials[Part Name],0)),"") | C27: =IFERROR(INDEX(M_RawMaterials[Category],MATCH($A27,M_RawMaterials[Part Name],0)),"") | D27: =IFERROR(INDEX(M_RawMaterials[基準在庫下限_要入力],MATCH($A27,M_RawMaterials[Part Name],0)),0) | E27: =IFERROR(INDEX(M_RawMaterials[基準在庫上限_要入力],MATCH($A27,M_RawMaterials[Part Name],0)),0) | F27: =IFERROR(LOOKUP(2,1/('T_SelfStock'!$B$16:$DA$16<>""),'T_SelfStock'!$B$16:$DA$16),"") | G27: =IFERROR(LOOKUP(2,1/('T_TTAFStock'!$B$16:$DA$16<>""),'T_TTAFStock'!$B$16:$DA$16),"") | H27: =IFERROR(LOOKUP(2,1/('T_SelfStock'!$B$16:$DA$16<>""),'T_SelfStock'!$B$5:$DA$5),"") | I27: 理論在庫 | J27: =IFERROR(INDEX('Grid_Stock'!$A12:$DA12,1,LOOKUP(2,1/('T_SelfStock'!$B$16:$DA$16<>""),COLUMN('T_SelfStock'!$B$16:$DA$16)))-INDEX('Grid_TheoreticalStock'!$A12:$DA12,1,LOOKUP(2,1/('T_SelfStock'!$B$16:$DA$16<>""),COLUMN('T_SelfStock'!$B$16:$DA$16))),0) | K27: ='Grid_TheoreticalStock'!B12 | L27: ='Grid_TheoreticalStock'!C12 | M27: ='Grid_TheoreticalStock'!D12 | N27: ='Grid_TheoreticalStock'!E12 | O27: ='Grid_TheoreticalStock'!F12 | P27: ='Grid_TheoreticalStock'!G12 | Q27: ='Grid_TheoreticalStock'!H12 | R27: ='Grid_TheoreticalStock'!I12 | ... DJ27: ='Grid_TheoreticalStock'!DA12
A28: YAN | B28: =IFERROR(INDEX(M_RawMaterials[Description],MATCH($A28,M_RawMaterials[Part Name],0)),"") | C28: =IFERROR(INDEX(M_RawMaterials[Category],MATCH($A28,M_RawMaterials[Part Name],0)),"") | D28: =IFERROR(INDEX(M_RawMaterials[基準在庫下限_要入力],MATCH($A28,M_RawMaterials[Part Name],0)),0) | E28: =IFERROR(INDEX(M_RawMaterials[基準在庫上限_要入力],MATCH($A28,M_RawMaterials[Part Name],0)),0) | F28: =IFERROR(LOOKUP(2,1/('T_SelfStock'!$B$16:$DA$16<>""),'T_SelfStock'!$B$16:$DA$16),"") | G28: =IFERROR(LOOKUP(2,1/('T_TTAFStock'!$B$16:$DA$16<>""),'T_TTAFStock'!$B$16:$DA$16),"") | H28: =IFERROR(LOOKUP(2,1/('T_SelfStock'!$B$16:$DA$16<>""),'T_SelfStock'!$B$5:$DA$5),"") | I28: 実在庫 | J28: =IFERROR(INDEX('Grid_Stock'!$A12:$DA12,1,LOOKUP(2,1/('T_SelfStock'!$B$16:$DA$16<>""),COLUMN('T_SelfStock'!$B$16:$DA$16)))-INDEX('Grid_TheoreticalStock'!$A12:$DA12,1,LOOKUP(2,1/('T_SelfStock'!$B$16:$DA$16<>""),COLUMN('T_SelfStock'!$B$16:$DA$16))),0) | K28: ='Grid_Stock'!B12 | L28: ='Grid_Stock'!C12 | M28: ='Grid_Stock'!D12 | N28: ='Grid_Stock'!E12 | O28: ='Grid_Stock'!F12 | P28: ='Grid_Stock'!G12 | Q28: ='Grid_Stock'!H12 | R28: ='Grid_Stock'!I12 | ... DJ28: ='Grid_Stock'!DA12
A29: ABN | B29: =IFERROR(INDEX(M_RawMaterials[Description],MATCH($A29,M_RawMaterials[Part Name],0)),"") | C29: =IFERROR(INDEX(M_RawMaterials[Category],MATCH($A29,M_RawMaterials[Part Name],0)),"") | D29: =IFERROR(INDEX(M_RawMaterials[基準在庫下限_要入力],MATCH($A29,M_RawMaterials[Part Name],0)),0) | E29: =IFERROR(INDEX(M_RawMaterials[基準在庫上限_要入力],MATCH($A29,M_RawMaterials[Part Name],0)),0) | F29: =IFERROR(LOOKUP(2,1/('T_SelfStock'!$B$17:$DA$17<>""),'T_SelfStock'!$B$17:$DA$17),"") | G29: =IFERROR(LOOKUP(2,1/('T_TTAFStock'!$B$17:$DA$17<>""),'T_TTAFStock'!$B$17:$DA$17),"") | H29: =IFERROR(LOOKUP(2,1/('T_SelfStock'!$B$17:$DA$17<>""),'T_SelfStock'!$B$5:$DA$5),"") | I29: 理論在庫 | J29: =IFERROR(INDEX('Grid_Stock'!$A13:$DA13,1,LOOKUP(2,1/('T_SelfStock'!$B$17:$DA$17<>""),COLUMN('T_SelfStock'!$B$17:$DA$17)))-INDEX('Grid_TheoreticalStock'!$A13:$DA13,1,LOOKUP(2,1/('T_SelfStock'!$B$17:$DA$17<>""),COLUMN('T_SelfStock'!$B$17:$DA$17))),0) | K29: ='Grid_TheoreticalStock'!B13 | L29: ='Grid_TheoreticalStock'!C13 | M29: ='Grid_TheoreticalStock'!D13 | N29: ='Grid_TheoreticalStock'!E13 | O29: ='Grid_TheoreticalStock'!F13 | P29: ='Grid_TheoreticalStock'!G13 | Q29: ='Grid_TheoreticalStock'!H13 | R29: ='Grid_TheoreticalStock'!I13 | ... DJ29: ='Grid_TheoreticalStock'!DA13
A30: ABN | B30: =IFERROR(INDEX(M_RawMaterials[Description],MATCH($A30,M_RawMaterials[Part Name],0)),"") | C30: =IFERROR(INDEX(M_RawMaterials[Category],MATCH($A30,M_RawMaterials[Part Name],0)),"") | D30: =IFERROR(INDEX(M_RawMaterials[基準在庫下限_要入力],MATCH($A30,M_RawMaterials[Part Name],0)),0) | E30: =IFERROR(INDEX(M_RawMaterials[基準在庫上限_要入力],MATCH($A30,M_RawMaterials[Part Name],0)),0) | F30: =IFERROR(LOOKUP(2,1/('T_SelfStock'!$B$17:$DA$17<>""),'T_SelfStock'!$B$17:$DA$17),"") | G30: =IFERROR(LOOKUP(2,1/('T_TTAFStock'!$B$17:$DA$17<>""),'T_TTAFStock'!$B$17:$DA$17),"") | H30: =IFERROR(LOOKUP(2,1/('T_SelfStock'!$B$17:$DA$17<>""),'T_SelfStock'!$B$5:$DA$5),"") | I30: 実在庫 | J30: =IFERROR(INDEX('Grid_Stock'!$A13:$DA13,1,LOOKUP(2,1/('T_SelfStock'!$B$17:$DA$17<>""),COLUMN('T_SelfStock'!$B$17:$DA$17)))-INDEX('Grid_TheoreticalStock'!$A13:$DA13,1,LOOKUP(2,1/('T_SelfStock'!$B$17:$DA$17<>""),COLUMN('T_SelfStock'!$B$17:$DA$17))),0) | K30: ='Grid_Stock'!B13 | L30: ='Grid_Stock'!C13 | M30: ='Grid_Stock'!D13 | N30: ='Grid_Stock'!E13 | O30: ='Grid_Stock'!F13 | P30: ='Grid_Stock'!G13 | Q30: ='Grid_Stock'!H13 | R30: ='Grid_Stock'!I13 | ... DJ30: ='Grid_Stock'!DA13
A31: OLJ | B31: =IFERROR(INDEX(M_RawMaterials[Description],MATCH($A31,M_RawMaterials[Part Name],0)),"") | C31: =IFERROR(INDEX(M_RawMaterials[Category],MATCH($A31,M_RawMaterials[Part Name],0)),"") | D31: =IFERROR(INDEX(M_RawMaterials[基準在庫下限_要入力],MATCH($A31,M_RawMaterials[Part Name],0)),0) | E31: =IFERROR(INDEX(M_RawMaterials[基準在庫上限_要入力],MATCH($A31,M_RawMaterials[Part Name],0)),0) | F31: =IFERROR(LOOKUP(2,1/('T_SelfStock'!$B$18:$DA$18<>""),'T_SelfStock'!$B$18:$DA$18),"") | G31: =IFERROR(LOOKUP(2,1/('T_TTAFStock'!$B$18:$DA$18<>""),'T_TTAFStock'!$B$18:$DA$18),"") | H31: =IFERROR(LOOKUP(2,1/('T_SelfStock'!$B$18:$DA$18<>""),'T_SelfStock'!$B$5:$DA$5),"") | I31: 理論在庫 | J31: =IFERROR(INDEX('Grid_Stock'!$A14:$DA14,1,LOOKUP(2,1/('T_SelfStock'!$B$18:$DA$18<>""),COLUMN('T_SelfStock'!$B$18:$DA$18)))-INDEX('Grid_TheoreticalStock'!$A14:$DA14,1,LOOKUP(2,1/('T_SelfStock'!$B$18:$DA$18<>""),COLUMN('T_SelfStock'!$B$18:$DA$18))),0) | K31: ='Grid_TheoreticalStock'!B14 | L31: ='Grid_TheoreticalStock'!C14 | M31: ='Grid_TheoreticalStock'!D14 | N31: ='Grid_TheoreticalStock'!E14 | O31: ='Grid_TheoreticalStock'!F14 | P31: ='Grid_TheoreticalStock'!G14 | Q31: ='Grid_TheoreticalStock'!H14 | R31: ='Grid_TheoreticalStock'!I14 | ... DJ31: ='Grid_TheoreticalStock'!DA14
A32: OLJ | B32: =IFERROR(INDEX(M_RawMaterials[Description],MATCH($A32,M_RawMaterials[Part Name],0)),"") | C32: =IFERROR(INDEX(M_RawMaterials[Category],MATCH($A32,M_RawMaterials[Part Name],0)),"") | D32: =IFERROR(INDEX(M_RawMaterials[基準在庫下限_要入力],MATCH($A32,M_RawMaterials[Part Name],0)),0) | E32: =IFERROR(INDEX(M_RawMaterials[基準在庫上限_要入力],MATCH($A32,M_RawMaterials[Part Name],0)),0) | F32: =IFERROR(LOOKUP(2,1/('T_SelfStock'!$B$18:$DA$18<>""),'T_SelfStock'!$B$18:$DA$18),"") | G32: =IFERROR(LOOKUP(2,1/('T_TTAFStock'!$B$18:$DA$18<>""),'T_TTAFStock'!$B$18:$DA$18),"") | H32: =IFERROR(LOOKUP(2,1/('T_SelfStock'!$B$18:$DA$18<>""),'T_SelfStock'!$B$5:$DA$5),"") | I32: 実在庫 | J32: =IFERROR(INDEX('Grid_Stock'!$A14:$DA14,1,LOOKUP(2,1/('T_SelfStock'!$B$18:$DA$18<>""),COLUMN('T_SelfStock'!$B$18:$DA$18)))-INDEX('Grid_TheoreticalStock'!$A14:$DA14,1,LOOKUP(2,1/('T_SelfStock'!$B$18:$DA$18<>""),COLUMN('T_SelfStock'!$B$18:$DA$18))),0) | K32: ='Grid_Stock'!B14 | L32: ='Grid_Stock'!C14 | M32: ='Grid_Stock'!D14 | N32: ='Grid_Stock'!E14 | O32: ='Grid_Stock'!F14 | P32: ='Grid_Stock'!G14 | Q32: ='Grid_Stock'!H14 | R32: ='Grid_Stock'!I14 | ... DJ32: ='Grid_Stock'!DA14
A33: 5SN | B33: =IFERROR(INDEX(M_RawMaterials[Description],MATCH($A33,M_RawMaterials[Part Name],0)),"") | C33: =IFERROR(INDEX(M_RawMaterials[Category],MATCH($A33,M_RawMaterials[Part Name],0)),"") | D33: =IFERROR(INDEX(M_RawMaterials[基準在庫下限_要入力],MATCH($A33,M_RawMaterials[Part Name],0)),0) | E33: =IFERROR(INDEX(M_RawMaterials[基準在庫上限_要入力],MATCH($A33,M_RawMaterials[Part Name],0)),0) | F33: =IFERROR(LOOKUP(2,1/('T_SelfStock'!$B$19:$DA$19<>""),'T_SelfStock'!$B$19:$DA$19),"") | G33: =IFERROR(LOOKUP(2,1/('T_TTAFStock'!$B$19:$DA$19<>""),'T_TTAFStock'!$B$19:$DA$19),"") | H33: =IFERROR(LOOKUP(2,1/('T_SelfStock'!$B$19:$DA$19<>""),'T_SelfStock'!$B$5:$DA$5),"") | I33: 理論在庫 | J33: =IFERROR(INDEX('Grid_Stock'!$A15:$DA15,1,LOOKUP(2,1/('T_SelfStock'!$B$19:$DA$19<>""),COLUMN('T_SelfStock'!$B$19:$DA$19)))-INDEX('Grid_TheoreticalStock'!$A15:$DA15,1,LOOKUP(2,1/('T_SelfStock'!$B$19:$DA$19<>""),COLUMN('T_SelfStock'!$B$19:$DA$19))),0) | K33: ='Grid_TheoreticalStock'!B15 | L33: ='Grid_TheoreticalStock'!C15 | M33: ='Grid_TheoreticalStock'!D15 | N33: ='Grid_TheoreticalStock'!E15 | O33: ='Grid_TheoreticalStock'!F15 | P33: ='Grid_TheoreticalStock'!G15 | Q33: ='Grid_TheoreticalStock'!H15 | R33: ='Grid_TheoreticalStock'!I15 | ... DJ33: ='Grid_TheoreticalStock'!DA15
A34: 5SN | B34: =IFERROR(INDEX(M_RawMaterials[Description],MATCH($A34,M_RawMaterials[Part Name],0)),"") | C34: =IFERROR(INDEX(M_RawMaterials[Category],MATCH($A34,M_RawMaterials[Part Name],0)),"") | D34: =IFERROR(INDEX(M_RawMaterials[基準在庫下限_要入力],MATCH($A34,M_RawMaterials[Part Name],0)),0) | E34: =IFERROR(INDEX(M_RawMaterials[基準在庫上限_要入力],MATCH($A34,M_RawMaterials[Part Name],0)),0) | F34: =IFERROR(LOOKUP(2,1/('T_SelfStock'!$B$19:$DA$19<>""),'T_SelfStock'!$B$19:$DA$19),"") | G34: =IFERROR(LOOKUP(2,1/('T_TTAFStock'!$B$19:$DA$19<>""),'T_TTAFStock'!$B$19:$DA$19),"") | H34: =IFERROR(LOOKUP(2,1/('T_SelfStock'!$B$19:$DA$19<>""),'T_SelfStock'!$B$5:$DA$5),"") | I34: 実在庫 | J34: =IFERROR(INDEX('Grid_Stock'!$A15:$DA15,1,LOOKUP(2,1/('T_SelfStock'!$B$19:$DA$19<>""),COLUMN('T_SelfStock'!$B$19:$DA$19)))-INDEX('Grid_TheoreticalStock'!$A15:$DA15,1,LOOKUP(2,1/('T_SelfStock'!$B$19:$DA$19<>""),COLUMN('T_SelfStock'!$B$19:$DA$19))),0) | K34: ='Grid_Stock'!B15 | L34: ='Grid_Stock'!C15 | M34: ='Grid_Stock'!D15 | N34: ='Grid_Stock'!E15 | O34: ='Grid_Stock'!F15 | P34: ='Grid_Stock'!G15 | Q34: ='Grid_Stock'!H15 | R34: ='Grid_Stock'!I15 | ... DJ34: ='Grid_Stock'!DA15
A35: 8EN | B35: =IFERROR(INDEX(M_RawMaterials[Description],MATCH($A35,M_RawMaterials[Part Name],0)),"") | C35: =IFERROR(INDEX(M_RawMaterials[Category],MATCH($A35,M_RawMaterials[Part Name],0)),"") | D35: =IFERROR(INDEX(M_RawMaterials[基準在庫下限_要入力],MATCH($A35,M_RawMaterials[Part Name],0)),0) | E35: =IFERROR(INDEX(M_RawMaterials[基準在庫上限_要入力],MATCH($A35,M_RawMaterials[Part Name],0)),0) | F35: =IFERROR(LOOKUP(2,1/('T_SelfStock'!$B$20:$DA$20<>""),'T_SelfStock'!$B$20:$DA$20),"") | G35: =IFERROR(LOOKUP(2,1/('T_TTAFStock'!$B$20:$DA$20<>""),'T_TTAFStock'!$B$20:$DA$20),"") | H35: =IFERROR(LOOKUP(2,1/('T_SelfStock'!$B$20:$DA$20<>""),'T_SelfStock'!$B$5:$DA$5),"") | I35: 理論在庫 | J35: =IFERROR(INDEX('Grid_Stock'!$A16:$DA16,1,LOOKUP(2,1/('T_SelfStock'!$B$20:$DA$20<>""),COLUMN('T_SelfStock'!$B$20:$DA$20)))-INDEX('Grid_TheoreticalStock'!$A16:$DA16,1,LOOKUP(2,1/('T_SelfStock'!$B$20:$DA$20<>""),COLUMN('T_SelfStock'!$B$20:$DA$20))),0) | K35: ='Grid_TheoreticalStock'!B16 | L35: ='Grid_TheoreticalStock'!C16 | M35: ='Grid_TheoreticalStock'!D16 | N35: ='Grid_TheoreticalStock'!E16 | O35: ='Grid_TheoreticalStock'!F16 | P35: ='Grid_TheoreticalStock'!G16 | Q35: ='Grid_TheoreticalStock'!H16 | R35: ='Grid_TheoreticalStock'!I16 | ... DJ35: ='Grid_TheoreticalStock'!DA16
A36: 8EN | B36: =IFERROR(INDEX(M_RawMaterials[Description],MATCH($A36,M_RawMaterials[Part Name],0)),"") | C36: =IFERROR(INDEX(M_RawMaterials[Category],MATCH($A36,M_RawMaterials[Part Name],0)),"") | D36: =IFERROR(INDEX(M_RawMaterials[基準在庫下限_要入力],MATCH($A36,M_RawMaterials[Part Name],0)),0) | E36: =IFERROR(INDEX(M_RawMaterials[基準在庫上限_要入力],MATCH($A36,M_RawMaterials[Part Name],0)),0) | F36: =IFERROR(LOOKUP(2,1/('T_SelfStock'!$B$20:$DA$20<>""),'T_SelfStock'!$B$20:$DA$20),"") | G36: =IFERROR(LOOKUP(2,1/('T_TTAFStock'!$B$20:$DA$20<>""),'T_TTAFStock'!$B$20:$DA$20),"") | H36: =IFERROR(LOOKUP(2,1/('T_SelfStock'!$B$20:$DA$20<>""),'T_SelfStock'!$B$5:$DA$5),"") | I36: 実在庫 | J36: =IFERROR(INDEX('Grid_Stock'!$A16:$DA16,1,LOOKUP(2,1/('T_SelfStock'!$B$20:$DA$20<>""),COLUMN('T_SelfStock'!$B$20:$DA$20)))-INDEX('Grid_TheoreticalStock'!$A16:$DA16,1,LOOKUP(2,1/('T_SelfStock'!$B$20:$DA$20<>""),COLUMN('T_SelfStock'!$B$20:$DA$20))),0) | K36: ='Grid_Stock'!B16 | L36: ='Grid_Stock'!C16 | M36: ='Grid_Stock'!D16 | N36: ='Grid_Stock'!E16 | O36: ='Grid_Stock'!F16 | P36: ='Grid_Stock'!G16 | Q36: ='Grid_Stock'!H16 | R36: ='Grid_Stock'!I16 | ... DJ36: ='Grid_Stock'!DA16
A37: 9RJ | B37: =IFERROR(INDEX(M_RawMaterials[Description],MATCH($A37,M_RawMaterials[Part Name],0)),"") | C37: =IFERROR(INDEX(M_RawMaterials[Category],MATCH($A37,M_RawMaterials[Part Name],0)),"") | D37: =IFERROR(INDEX(M_RawMaterials[基準在庫下限_要入力],MATCH($A37,M_RawMaterials[Part Name],0)),0) | E37: =IFERROR(INDEX(M_RawMaterials[基準在庫上限_要入力],MATCH($A37,M_RawMaterials[Part Name],0)),0) | F37: =IFERROR(LOOKUP(2,1/('T_SelfStock'!$B$21:$DA$21<>""),'T_SelfStock'!$B$21:$DA$21),"") | G37: =IFERROR(LOOKUP(2,1/('T_TTAFStock'!$B$21:$DA$21<>""),'T_TTAFStock'!$B$21:$DA$21),"") | H37: =IFERROR(LOOKUP(2,1/('T_SelfStock'!$B$21:$DA$21<>""),'T_SelfStock'!$B$5:$DA$5),"") | I37: 理論在庫 | J37: =IFERROR(INDEX('Grid_Stock'!$A17:$DA17,1,LOOKUP(2,1/('T_SelfStock'!$B$21:$DA$21<>""),COLUMN('T_SelfStock'!$B$21:$DA$21)))-INDEX('Grid_TheoreticalStock'!$A17:$DA17,1,LOOKUP(2,1/('T_SelfStock'!$B$21:$DA$21<>""),COLUMN('T_SelfStock'!$B$21:$DA$21))),0) | K37: ='Grid_TheoreticalStock'!B17 | L37: ='Grid_TheoreticalStock'!C17 | M37: ='Grid_TheoreticalStock'!D17 | N37: ='Grid_TheoreticalStock'!E17 | O37: ='Grid_TheoreticalStock'!F17 | P37: ='Grid_TheoreticalStock'!G17 | Q37: ='Grid_TheoreticalStock'!H17 | R37: ='Grid_TheoreticalStock'!I17 | ... DJ37: ='Grid_TheoreticalStock'!DA17
A38: 9RJ | B38: =IFERROR(INDEX(M_RawMaterials[Description],MATCH($A38,M_RawMaterials[Part Name],0)),"") | C38: =IFERROR(INDEX(M_RawMaterials[Category],MATCH($A38,M_RawMaterials[Part Name],0)),"") | D38: =IFERROR(INDEX(M_RawMaterials[基準在庫下限_要入力],MATCH($A38,M_RawMaterials[Part Name],0)),0) | E38: =IFERROR(INDEX(M_RawMaterials[基準在庫上限_要入力],MATCH($A38,M_RawMaterials[Part Name],0)),0) | F38: =IFERROR(LOOKUP(2,1/('T_SelfStock'!$B$21:$DA$21<>""),'T_SelfStock'!$B$21:$DA$21),"") | G38: =IFERROR(LOOKUP(2,1/('T_TTAFStock'!$B$21:$DA$21<>""),'T_TTAFStock'!$B$21:$DA$21),"") | H38: =IFERROR(LOOKUP(2,1/('T_SelfStock'!$B$21:$DA$21<>""),'T_SelfStock'!$B$5:$DA$5),"") | I38: 実在庫 | J38: =IFERROR(INDEX('Grid_Stock'!$A17:$DA17,1,LOOKUP(2,1/('T_SelfStock'!$B$21:$DA$21<>""),COLUMN('T_SelfStock'!$B$21:$DA$21)))-INDEX('Grid_TheoreticalStock'!$A17:$DA17,1,LOOKUP(2,1/('T_SelfStock'!$B$21:$DA$21<>""),COLUMN('T_SelfStock'!$B$21:$DA$21))),0) | K38: ='Grid_Stock'!B17 | L38: ='Grid_Stock'!C17 | M38: ='Grid_Stock'!D17 | N38: ='Grid_Stock'!E17 | O38: ='Grid_Stock'!F17 | P38: ='Grid_Stock'!G17 | Q38: ='Grid_Stock'!H17 | R38: ='Grid_Stock'!I17 | ... DJ38: ='Grid_Stock'!DA17
A39: 5JK | B39: =IFERROR(INDEX(M_RawMaterials[Description],MATCH($A39,M_RawMaterials[Part Name],0)),"") | C39: =IFERROR(INDEX(M_RawMaterials[Category],MATCH($A39,M_RawMaterials[Part Name],0)),"") | D39: =IFERROR(INDEX(M_RawMaterials[基準在庫下限_要入力],MATCH($A39,M_RawMaterials[Part Name],0)),0) | E39: =IFERROR(INDEX(M_RawMaterials[基準在庫上限_要入力],MATCH($A39,M_RawMaterials[Part Name],0)),0) | F39: =IFERROR(LOOKUP(2,1/('T_SelfStock'!$B$22:$DA$22<>""),'T_SelfStock'!$B$22:$DA$22),"") | G39: =IFERROR(LOOKUP(2,1/('T_TTAFStock'!$B$22:$DA$22<>""),'T_TTAFStock'!$B$22:$DA$22),"") | H39: =IFERROR(LOOKUP(2,1/('T_SelfStock'!$B$22:$DA$22<>""),'T_SelfStock'!$B$5:$DA$5),"") | I39: 理論在庫 | J39: =IFERROR(INDEX('Grid_Stock'!$A18:$DA18,1,LOOKUP(2,1/('T_SelfStock'!$B$22:$DA$22<>""),COLUMN('T_SelfStock'!$B$22:$DA$22)))-INDEX('Grid_TheoreticalStock'!$A18:$DA18,1,LOOKUP(2,1/('T_SelfStock'!$B$22:$DA$22<>""),COLUMN('T_SelfStock'!$B$22:$DA$22))),0) | K39: ='Grid_TheoreticalStock'!B18 | L39: ='Grid_TheoreticalStock'!C18 | M39: ='Grid_TheoreticalStock'!D18 | N39: ='Grid_TheoreticalStock'!E18 | O39: ='Grid_TheoreticalStock'!F18 | P39: ='Grid_TheoreticalStock'!G18 | Q39: ='Grid_TheoreticalStock'!H18 | R39: ='Grid_TheoreticalStock'!I18 | ... DJ39: ='Grid_TheoreticalStock'!DA18
